Workbook

Sheet RANCM-sdrPlan
A1: cellnum | B1: 扩容类型 | C1: 制式 | D1: mimType | E1: mimVersion | F1: RADIOMODE | G1: SWVERSION | H1: Slot1 | I1: Slot2 | J1: Slot3 | K1: Slot4 | L1: Slot5 | M1: Slot6 | N1: Slot7 | O1: Slot8 | P1: Slot9 | Q1: Slot10 | R1: Slot11 | S1: Slot12 | T1: Slot13 | U1: Slot14 | V1: Slot15 | W1: Slot16 | X1: Slot17 | Y1: RUDevice | Z1: userLabel1 | AA1: RUType | AB1: functionMode | AC1: connectModeWithUpRack | AD1: fddServiceDscpMap | AE1: tddServiceDscpMap | AF1: refRfDevice | AG1: AntProfile | AH1: vid | AI1: ipAddr | AJ1: networkMask | AK1: gatewayIp | AL1: SubNetwork | AM1: ManagedElement | AN1: NE_Name | AO1: moId | AP1: ptpDomain | AQ1: cellLocalId | AR1: userLabel2 | AS1: pci | AT1: tac | AU1: rootSequenceIndex | AV1: FDD/TDD | AW1: ref1SdrDeviceGroup | AX1: refRfDevice | AY1: freqBandInd | AZ1: earfcnUl | BA1: earfcnDl | BB1: bandWidthDl | BC1: bandWidthUl | BD1: maxUeRbNumUl | BE1: maxUeRbNumDl | BF1: refBpDevice2 | BG1: refBpDevice | BH1: cpSpeRefSigPwr | BI1: antMapDlSeq | BJ1: antMapUlSeq | BK1: upActAntBitmapSeq | BL1: anttoPortMap | BM1: isDelNbrAndRelation | BN1: AntProfile | BO1: cellMod | BP1: slot17 | BQ1: PM,0,0 | BR1: slot6 | BT1: slot12
A2: 小区数 | D2: 模型类型 | E2: 模型标识 | F2: 无线制式 | G2: 网元配置数据版本 | H2: 这个槽位上的单板信息 | I2: 这个槽位上的单板信息 | J2: 这个槽位上的单板信息 | K2: 这个槽位上的单板信息 | L2: 这个槽位上的单板信息 | M2: 这个槽位上的单板信息 | N2: 这个槽位上的单板信息 | O2: 这个槽位上的单板信息 | P2: 这个槽位上的单板信息 | Q2: 这个槽位上的单板信息 | R2: 这个槽位上的单板信息 | S2: 这个槽位上的单板信息 | T2: 这个槽位上的单板信息 | U2: 这个槽位上的单板信息 | V2: 这个槽位上的单板信息 | W2: 这个槽位上的单板信息 | X2: 这个槽位上的单板信息 | Y2: RU设备 | Z2: RRU子架描述信息 | AA2: RU类型 | AB2: 单板功能模式 | AD2: LTE FDD业务与DSCP映射(链路承载的业务将会中断。) | AE2: TD-LTE业务与DSCP映射(链路承载的业务将会中断。) | AF2: 射频口对象 | AG2: 使用的天线属性 | AH2: VLAN ID | AI2: IP地址 | AJ2: 掩码 | AK2: 网关IP | AO2: 对象标识 | AP2: PTP域号 | AQ2: 小区标识 | AR2: 小区用户标识 | AS2: 物理小区识别码 | AT2: 跟踪区码 | AU2: PrachFDD 产生64个前缀序列的逻辑根序列的起始索引号 | AW2: 使用的RRU（小区复位生效） | AX2: 射频口对象 | AY2: 频段指示 | AZ2: 上行链路的中心载频(MHz) | BA2: 下行链路的中心载频(MHz) | BB2: 小区下行系统频域带宽(MHz) | BC2: 小区上行系统频域带宽(MHz) | BD2: 上行UE最大分配RB数 | BE2: 下行UE最大分配RB数 | BF2: 关联的基带设备 | BG2: 关联的基带设备 | BH2: 基带资源参考信号功率(dBm) | BI2: 下行天线配置映射位图（小区复位生效） | BJ2: 上行天线配置映射位图(小区复位生效) | BK2: 上行激活天线位图(小区复位生效) | BL2: 天线端口与天线通道的映射关系 | BM2: 是否连带删除UME内的邻接小区、邻接关系 | BN2: 使用的天线属性 | BO2: 小区模式（小区复位生效） | BP2: slot16 | BR2: slot5 | BT2: slot11
A3: string | D3: string:length[0..80] | E3: string:length[0..80] | F3: string:length[0..128] | G3: string:length[0..128] | H3: string:length[0..128] | I3: string:length[0..128] | J3: string:length[0..128] | K3: string:length[0..128] | L3: string:length[0..128] | M3: string:length[0..128] | N3: string:length[0..128] | O3: string:length[0..128] | P3: string:length[0..128] | Q3: string:length[0..128] | R3: string:length[0..128] | S3: string:length[0..128] | T3: string:length[0..128] | U3: string:length[0..128] | V3: string:length[0..128] | W3: string:length[0..128] | X3: string:length[0..128] | Y3: string:length[0..1024] | Z3: string:length[0..128] | AA3: string:length[0..201] | AB3: long:[-9223372036854775808..9223372036854775807] | AD3: string:length[0..300] | AE3: string:length[0..300] | AF3: string:length[0..500] | AG3: string:length[0..1024] | AH3: long:[1..4094] | AI3: union:[ipv4-address, ipv6-address] | AJ3: union:[ipv4-address, ipv6-address] 默认值: 255.255.255.0 | AK3: union:[ipv4-address, ipv6-address] 默认值: 0.0.0.0 | AO3: string:length[1..255] | AP3: long:[0..255] 默认值: 0 | AQ3: long:[0..255] | AR3: string:length[0..128] | AS3: long:[0..503] 默认值: 0 | AT3: long:[0..65535] 默认值: 0 | AU3: long:[0..837] 默认值: 0 | AW3: string:length[0..500] | AX3: string:length[0..500] | AY3: long:[1..5, 7..14, 17..28, 31..32, 46, 65..76, 85, 87..88, 101] 默认值: 1 | AZ3: double:[410..417, 450..457.5, 663..758, 777..787, 788..798, 807..862, 880..915, 962..977, 1427..1517, 1626.5..1660.5, 1695..1785, 1850..1915, 1920..2020, 2500..2620, 3410..3490, 5150..5925] 默认值: 1930.0 | BA3: double:[420..427, 460..467.5, 617..652, 728..821, 852..894, 925..960, 1035..1057, 1427..1518, 1525..1559, 1805..1880, 1930..2020, 2110..2200, 2570..2690, 3510..3590, 5150..5925] 默认值: 2120.0 | BB3: enum: 1.4(6RB)[0] 3(15RB)[1] 5(25RB)[2] 10(50RB)[3] 15(75RB)[4] 20(100RB)[5] 8(40RB)[6] 16(80RB)[7] 4.4(23RB)[8] 2.4M[9] 2.6M[10] 2.8M[11] 4.6M[12] 4.8M[13] 7.2M[14] 7.4M[15] 7.6M[16] 7.8M[17] 8.2M[18] 8.4M[19] 8.6M[20] 8.8M[21] 9M[22] 9.2M[23] 13.2M[24] 13.6M[25] 14M[26] 17.4M[27] 17.8M[28] 18.2M[29] 18.6M[30] 7.5M[31] 14.8M[32] 默认值: 5 | BC3: enum: 1.4(6RB)[0] 3(15RB)[1] 5(25RB)[2] 10(50RB)[3] 15(75RB)[4] 20(100RB)[5] 8(40RB)[6] 16(80RB)[7] 4.4(23RB)[8] 2.4M[9] 2.6M[10] 2.8M[11] 4.6M[12] 4.8M[13] 7.2M[14] 7.4M[15] 7.6M[16] 7.8M[17] 8.2M[18] 8.4M[19] 8.6M[20] 8.8M[21] 9M[22] 9.2M[23] 13.2M[24] 13.6M[25] 14M[26] 17.4M[27] 17.8M[28] 18.2M[29] 18.6M[30] 7.5M[31] 14.8M[32] 默认值: 5 | BD3: enum: 2[1] 3[2] 4[3] 5[4] 6[5] 8[6] 9[7] 10[8] 12[9] 15[10] 16[11] 18[12] 20[13] 24[14] 25[15] 27[16] 30[17] 32[18] 36[19] 40[20] 45[21] 48[22] 50[23] 54[24] 60[25] 64[26] 72[27] 75[28] 80[29] 81[30] 90[31] 96[32] 100[33] 默认值: 33 | BE3: long:[1..100] 默认值: 100 | BF3: string:length[0..500] | BG3: string:length[0..500] | BH3: string:length[0..500] | BI3: string:length[0..2000] | BJ3: string:length[0..2000] | BK3: string:length[0..2000] | BL3: string:length[0..2500] | BM3: enum: 不连带删除[0] 连带删除[1] 默认值: 0 | BN3: string:length[0..1024] | BO3: string:length[0..500] | BP3: slot15 | BQ3: FAB,0,0 | BR3: slot4 | BT3: slot10

Sheet 填表说明
A1: cellnum | B1: 扩容类型 | C1: 制式 | D1: mimType | E1: mimVersion | F1: RADIOMODE | G1: SWVERSION | H1: Slot1 | I1: Slot2 | J1: Slot3 | K1: Slot4 | L1: Slot5 | M1: Slot6 | N1: Slot7 | O1: Slot8 | P1: Slot9 | Q1: Slot10 | R1: Slot11 | S1: Slot12 | T1: Slot13 | U1: Slot14 | V1: Slot15 | W1: Slot16 | X1: Slot17 | Y1: RUDevice | Z1: userLabel1 | AA1: RUType | AB1: functionMode | AC1: connectModeWithUpRack | AD1: fddServiceDscpMap | AE1: tddServiceDscpMap | AF1: refRfDevice | AG1: AntProfile | AH1: vid | AI1: ipAddr | AJ1: networkMask | AK1: gatewayIp | AL1: SubNetwork | AM1: ManagedElement | AN1: NE_Name | AO1: moId | AP1: ptpDomain | AQ1: cellLocalId | AR1: userLabel2 | AS1: pci | AT1: tac | AU1: rootSequenceIndex | AV1: FDD/TDD | AW1: ref1SdrDeviceGroup | AX1: freqBandInd | AY1: earfcnUl | AZ1: earfcnDl | BA1: bandWidthDl | BB1: bandWidthUl | BC1: maxUeRbNumUl | BD1: maxUeRbNumDl | BE1: LONGITUDE | BF1: LATITUDE | BG1: rfAppMode | BH1: refBpDevice2 | BI1: refBpDevice | BJ1: cpSpeRefSigPwr | BK1: antMapDlSeq | BL1: antMapUlSeq | BM1: upActAntBitmapSeq | BN1: anttoPortMap | BO1: isDelNbrAndRelation | BQ1: cellMod | BR1: slot17 | BS1: PM,0,0 | BT1: slot6 | BV1: slot12
A2: 小区数 | D2: 模型类型 | E2: 模型标识 | F2: 无线制式 | G2: 网元配置数据版本 | H2: 这个槽位上的单板信息 | I2: 这个槽位上的单板信息 | J2: 这个槽位上的单板信息 | K2: 这个槽位上的单板信息 | L2: 这个槽位上的单板信息 | M2: 这个槽位上的单板信息 | N2: 这个槽位上的单板信息 | O2: 这个槽位上的单板信息 | P2: 这个槽位上的单板信息 | Q2: 这个槽位上的单板信息 | R2: 这个槽位上的单板信息 | S2: 这个槽位上的单板信息 | T2: 这个槽位上的单板信息 | U2: 这个槽位上的单板信息 | V2: 这个槽位上的单板信息 | W2: 这个槽位上的单板信息 | X2: 这个槽位上的单板信息 | Y2: RU设备 | Z2: RRU子架描述信息 | AA2: RU类型 | AB2: 单板功能模式 | AD2: LTE FDD业务与DSCP映射(链路承载的业务将会中断。) | AE2: TD-LTE业务与DSCP映射(链路承载的业务将会中断。) | AF2: 射频口对象 | AG2: 使用的天线属性 | AH2: VLAN ID | AI2: IP地址 | AJ2: 掩码 | AK2: 网关IP | AO2: 对象标识 | AP2: PTP域号 | AQ2: 小区标识 | AR2: 小区用户标识 | AS2: 物理小区识别码 | AT2: 跟踪区码 | AU2: PrachFDD 产生64个前缀序列的逻辑根序列的起始索引号 | AW2: 使用的RRU（小区复位生效） | AX2: 频段指示 | AY2: 上行链路的中心载频(MHz) | AZ2: 下行链路的中心载频(MHz) | BA2: 小区下行系统频域带宽(MHz) | BB2: 小区上行系统频域带宽(MHz) | BC2: 上行UE最大分配RB数 | BD2: 下行UE最大分配RB数 | BH2: 关联的基带设备 | BI2: 关联的基带设备 | BJ2: 基带资源参考信号功率(dBm) | BK2: 下行天线配置映射位图（小区复位生效） | BL2: 上行天线配置映射位图(小区复位生效) | BM2: 上行激活天线位图(小区复位生效) | BN2: 天线端口与天线通道的映射关系 | BO2: 是否连带删除UME内的邻接小区、邻接关系 | BQ2: 小区模式（小区复位生效） | BR2: slot16 | BT2: slot5 | BV2: slot11
A3: string | D3: string:length[0..80] | E3: string:length[0..80] | F3: string:length[0..128] | G3: string:length[0..128] | H3: string:length[0..128] | I3: string:length[0..128] | J3: string:length[0..128] | K3: string:length[0..128] | L3: string:length[0..128] | M3: string:length[0..128] | N3: string:length[0..128] | O3: string:length[0..128] | P3: string:length[0..128] | Q3: string:length[0..128] | R3: string:length[0..128] | S3: string:length[0..128] | T3: string:length[0..128] | U3: string:length[0..128] | V3: string:length[0..128] | W3: string:length[0..128] | X3: string:length[0..128] | Y3: string:length[0..1024] | Z3: string:length[0..128] | AA3: string:length[0..201] | AB3: long:[-9223372036854775808..9223372036854775807] | AD3: string:length[0..300] | AE3: string:length[0..300] | AF3: string:length[0..500] | AG3: string:length[0..1024] | AH3: long:[1..4094] | AI3: union:[ipv4-address, ipv6-address] | AJ3: union:[ipv4-address, ipv6-address] 默认值: 255.255.255.0 | AK3: union:[ipv4-address, ipv6-address] 默认值: 0.0.0.0 | AO3: string:length[1..255] | AP3: long:[0..255] 默认值: 0 | AQ3: long:[0..255] | AR3: string:length[0..128] | AS3: long:[0..503] 默认值: 0 | AT3: long:[0..65535] 默认值: 0 | AU3: long:[0..837] 默认值: 0 | AW3: string:length[0..500] | AX3: long:[1..5, 7..14, 17..28, 31..32, 46, 65..76, 85, 87..88, 101] 默认值: 1 | AY3: double:[410..417, 450..457.5, 663..758, 777..787, 788..798, 807..862, 880..915, 962..977, 1427..1517, 1626.5..1660.5, 1695..1785, 1850..1915, 1920..2020, 2500..2620, 3410..3490, 5150..5925] 默认值: 1930.0 | AZ3: double:[420..427, 460..467.5, 617..652, 728..821, 852..894, 925..960, 1035..1057, 1427..1518, 1525..1559, 1805..1880, 1930..2020, 2110..2200, 2570..2690, 3510..3590, 5150..5925] 默认值: 2120.0 | BA3: enum: 1.4(6RB)[0] 3(15RB)[1] 5(25RB)[2] 10(50RB)[3] 15(75RB)[4] 20(100RB)[5] 8(40RB)[6] 16(80RB)[7] 4.4(23RB)[8] 2.4M[9] 2.6M[10] 2.8M[11] 4.6M[12] 4.8M[13] 7.2M[14] 7.4M[15] 7.6M[16] 7.8M[17] 8.2M[18] 8.4M[19] 8.6M[20] 8.8M[21] 9M[22] 9.2M[23] 13.2M[24] 13.6M[25] 14M[26] 17.4M[27] 17.8M[28] 18.2M[29] 18.6M[30] 7.5M[31] 14.8M[32] 默认值: 5 | BB3: enum: 1.4(6RB)[0] 3(15RB)[1] 5(25RB)[2] 10(50RB)[3] 15(75RB)[4] 20(100RB)[5] 8(40RB)[6] 16(80RB)[7] 4.4(23RB)[8] 2.4M[9] 2.6M[10] 2.8M[11] 4.6M[12] 4.8M[13] 7.2M[14] 7.4M[15] 7.6M[16] 7.8M[17] 8.2M[18] 8.4M[19] 8.6M[20] 8.8M[21] 9M[22] 9.2M[23] 13.2M[24] 13.6M[25] 14M[26] 17.4M[27] 17.8M[28] 18.2M[29] 18.6M[30] 7.5M[31] 14.8M[32] 默认值: 5 | BC3: enum: 2[1] 3[2] 4[3] 5[4] 6[5] 8[6] 9[7] 10[8] 12[9] 15[10] 16[11] 18[12] 20[13] 24[14] 25[15] 27[16] 30[17] 32[18] 36[19] 40[20] 45[21] 48[22] 50[23] 54[24] 60[25] 64[26] 72[27] 75[28] 80[29] 81[30] 90[31] 96[32] 100[33] 默认值: 33 | BD3: long:[1..100] 默认值: 100 | BH3: string:length[0..500] | BI3: string:length[0..500] | BJ3: string:length[0..500] | BK3: string:length[0..2000] | BL3: string:length[0..2000] | BM3: string:length[0..2000] | BN3: string:length[0..2500] | BO3: enum: 不连带删除[0] 连带删除[1] 默认值: 0 | BQ3: string:length[0..500] | BR3: slot15 | BS3: FAB,0,0 | BT3: slot4 | BV3: slot10
A4: 3 | B4: 软扩 | C4: TDDtoTDD；FDDtoFDD | D4: LTE-TDD | E4: TDL_D_V6.10.20.00 | F4: 32 | G4: =_xlfn.XLOOKUP(E4,E12:E17,G12:G17,,0,1) -> UniRan 12.4(LTE V5.50.51) | H4: =BU6&" " -> CCC,0,0 | I4: =BU5&" " | J4: =BU4&" " | K4: =BU3&" " | L4: =BU2&" " | M4: =BU1&" " | N4: =BW6&" " | O4: =BW5&" " | P4: =BW4&" " -> BPN2,32,100671497 | Q4: =BW3&" " | R4: =BW2&" " | S4: =BW1&" " | T4: =BS6&" " | U4: =BS4&" " | V4: =BS3&" " -> FAB,0,0 | W4: =BS2&" " | X4: =BS1&" " -> PM,0,0 | Y4: 84 | Z4: 丰台西山湖文苑北2-ZLH-LF-201-RRU01 | AA4: R8978 M1920A | AB4: =VLOOKUP(AA4,$AA$12:$AB$31,2,FALSE) -> 452984881 | AD4: =IF(LEFT(AV4,3)="FDD","0;1;2;3;4;5;6;7;8;9;10;11;12;13;14;15;16;17;18;19;20;21;22;23;24;25;26;27;28;29;30;31;32;33;34;35;36;37;38;39;40;41;42;43;44;45;46;47;48;49;50;51;52;53;54;55;56;57;58;59;60;61;62;63"," ") | AE4: =IF(LEFT(AV4,3)="TDD","0;1;2;3;4;5;6;7;8;9;10;11;12;13;14;15;16;17;18;19;20;21;22;23;24;25;26;27;28;29;30;31;32;33;34;35;36;37;38;39;40;41;42;43;44;45;46;47;48;49;50;51;52;53;54;55;56;57;58;59;60;61;62;63"," ") -> 0;1;2;3;4;5;6;7;8;9;10;11;12;13;14;15;16;17;18;19;20;21;22;23;24;25;26;27;28;29;30;31;32;33;34;35;36;37;38;39;40;41;42;43;44;45;46;47;48;49;50;51;52;53;54;55;56;57;58;59;60;61;62;63 | AF4: =VLOOKUP(K4&#REF!,RRU频段及通道配置FDD!#REF!,2,0) -> #REF! | AG4: =VLOOKUP(#REF!,RRU频段及通道配置FDD!#REF!,20,0) -> #REF! | AH4: 1001 | AI4: 10.152.17.202 | AJ4: 255.255.255.252 | AK4: 10.152.17.201 | AO4: 1 | AP4: 24 | AQ4: 201 | AR4: 丰台西山湖文苑北2-ZLH-LF-201 | AS4: 165 | AT4: 4148 | AU4: 768 | AV4: TDD-F1 | AW4: =Y4 -> 84 | AX4: =_xlfn.XLOOKUP(AV4,$AV$12:$AV$24,$AX$12:$AX$24,,1,1) -> 39 | AY4: =_xlfn.XLOOKUP(AV4,$AV$12:$AV$24,$AY$12:$AY$24,,1,1) -> 1895 | AZ4: =_xlfn.XLOOKUP(AV4,$AV$12:$AV$24,$AX$12:$BD$24,,1,1)&" " | BA4: =_xlfn.XLOOKUP(AV4,$AV$12:$AV$24,$BA$12:$BD$24,,1,1) -> 20(100RB)[5] | BB4: =_xlfn.XLOOKUP(AV4,$AV$12:$AV$24,$AX$12:$BD$24,,1,1) -> 5 | BC4: =_xlfn.XLOOKUP(AV4,$AV$12:$AV$24,$BD$12:$BD$24,,0,1) -> 100[33] | BD4: =_xlfn.XLOOKUP(AV4,$AV$12:$AV$24,$BC$12:$BC$24,,1,1) -> 100 | BH4: 9 | BI4: 9:0 | BJ4: 15.2 | BK4: =VLOOKUP(AA:AA,RRU频段及通道配置FDD!A:P,16,0) -> 1;1;1;1;1;1;1;1;0;0;0;0;0;0;0;0;0;0;0;0;0;0;0;0;0;0;0;0;0;0;0;0;0;0;0;0;0;0;0;0;0;0;0;0;0;0;0;0;0;0;0;0;0;0;0;0;0;0;0;0;0;0;0;0 | BL4: =VLOOKUP(AA:AA,RRU频段及通道配置FDD!A:P,16,0)&" " -> 1;1;1;1;1;1;1;1;0;0;0;0;0;0;0;0;0;0;0;0;0;0;0;0;0;0;0;0;0;0;0;0;0;0;0;0;0;0;0;0;0;0;0;0;0;0;0;0;0;0;0;0;0;0;0;0;0;0;0;0;0;0;0;0 | BM4: =VLOOKUP(AA:AA,RRU频段及通道配置FDD!A:P,16,0)&" " -> 1;1;1;1;1;1;1;1;0;0;0;0;0;0;0;0;0;0;0;0;0;0;0;0;0;0;0;0;0;0;0;0;0;0;0;0;0;0;0;0;0;0;0;0;0;0;0;0;0;0;0;0;0;0;0;0;0;0;0;0;0;0;0;0 | BN4: =VLOOKUP(AA:AA,RRU频段及通道配置FDD!A:Q,17,0) -> 0;0;0;0;1;1;1;1;15;15;15;15;15;15;15;15;15;15;15;15;15;15;15;15;15;15;15;15;15;15;15;15;15;15;15;15;15;15;15;15;15;15;15;15;15;15;15;15;15;15;15;15;15;15;15;15;15;15;15;15;15;15;15;15 | BO4: 0 | BQ4: =VLOOKUP(AA:AA,RRU频段及通道配置FDD!A:T,19,0) -> 1 | BR4: slot14 | BT4: slot3 | BV4: slot9 | BW4: BPN2,32,100671497
Y5: 85 | Z5: 丰台西山湖文苑北2-ZLH-LF-202-RRU02 | AA5: R8978 M1920A | AB5: =VLOOKUP(AA5,$AA$12:$AB$31,2,FALSE) -> 452984881 | AD5: =IF(LEFT(AV4,3)="FDD","0;1;2;3;4;5;6;7;8;9;10;11;12;13;14;15;16;17;18;19;20;21;22;23;24;25;26;27;28;29;30;31;32;33;34;35;36;37;38;39;40;41;42;43;44;45;46;47;48;49;50;51;52;53;54;55;56;57;58;59;60;61;62;63"," ") | AE5: =IF(LEFT(AV4,3)="TDD","0;1;2;3;4;5;6;7;8;9;10;11;12;13;14;15;16;17;18;19;20;21;22;23;24;25;26;27;28;29;30;31;32;33;34;35;36;37;38;39;40;41;42;43;44;45;46;47;48;49;50;51;52;53;54;55;56;57;58;59;60;61;62;63"," ") -> 0;1;2;3;4;5;6;7;8;9;10;11;12;13;14;15;16;17;18;19;20;21;22;23;24;25;26;27;28;29;30;31;32;33;34;35;36;37;38;39;40;41;42;43;44;45;46;47;48;49;50;51;52;53;54;55;56;57;58;59;60;61;62;63 | AF5: =VLOOKUP(K5&#REF!,RRU频段及通道配置FDD!#REF!,2,0) -> #REF! | AG5: =VLOOKUP(#REF!,RRU频段及通道配置FDD!#REF!,20,0) -> #REF! | AH5: 101 | AI5: 10.133.17.202 | AJ5: 255.255.255.252 | AK5: 10.133.17.201 | AO5: 2 | AQ5: 202 | AR5: 丰台西山湖文苑北2-ZLH-LF-202 | AS5: 166 | AT5: 4148 | AU5: 772 | AV5: TDD-F1 | AW5: =Y5 -> 85 | AX5: =_xlfn.XLOOKUP(AV5,$AV$12:$AV$24,$AX$12:$AX$24,,1,1) -> 39 | AY5: =_xlfn.XLOOKUP(AV5,$AV$12:$AV$24,$AY$12:$AY$24,,1,1) -> 1895 | AZ5: =_xlfn.XLOOKUP(AV5,$AV$12:$AV$24,$AZ$12:$AZ$24,,1,1)&" " | BA5: =_xlfn.XLOOKUP(AV5,$AV$12:$AV$24,$BA$12:$BA$24,,1,1) -> 20(100RB)[5] | BB5: =_xlfn.XLOOKUP(AV5,$AV$12:$AV$24,$AX$12:$BD$24,,1,1) -> 5 | BC5: =_xlfn.XLOOKUP(AV5,$AV$12:$AV$24,$BD$12:$BD$24,,0,1) -> 100[33] | BD5: =_xlfn.XLOOKUP(AV5,$AV$12:$AV$24,$BC$12:$BC$24,,1,1) -> 100 | BH5: 9 | BI5: 9:0 | BJ5: 15.2 | BK5: =VLOOKUP(AA:AA,RRU频段及通道配置FDD!A:P,16,0) -> 1;1;1;1;1;1;1;1;0;0;0;0;0;0;0;0;0;0;0;0;0;0;0;0;0;0;0;0;0;0;0;0;0;0;0;0;0;0;0;0;0;0;0;0;0;0;0;0;0;0;0;0;0;0;0;0;0;0;0;0;0;0;0;0 | BL5: =VLOOKUP(AA:AA,RRU频段及通道配置FDD!A:P,16,0)&" " -> 1;1;1;1;1;1;1;1;0;0;0;0;0;0;0;0;0;0;0;0;0;0;0;0;0;0;0;0;0;0;0;0;0;0;0;0;0;0;0;0;0;0;0;0;0;0;0;0;0;0;0;0;0;0;0;0;0;0;0;0;0;0;0;0 | BM5: =VLOOKUP(AA:AA,RRU频段及通道配置FDD!A:P,16,0)&" " -> 1;1;1;1;1;1;1;1;0;0;0;0;0;0;0;0;0;0;0;0;0;0;0;0;0;0;0;0;0;0;0;0;0;0;0;0;0;0;0;0;0;0;0;0;0;0;0;0;0;0;0;0;0;0;0;0;0;0;0;0;0;0;0;0 | BN5: =VLOOKUP(AA:AA,RRU频段及通道配置FDD!A:Q,17,0) -> 0;0;0;0;1;1;1;1;15;15;15;15;15;15;15;15;15;15;15;15;15;15;15;15;15;15;15;15;15;15;15;15;15;15;15;15;15;15;15;15;15;15;15;15;15;15;15;15;15;15;15;15;15;15;15;15;15;15;15;15;15;15;15;15 | BO5: 0 | BQ5: =VLOOKUP(AA:AA,RRU频段及通道配置FDD!A:T,19,0) -> 1 | BT5: slot2 | BV5: slot8
Y6: 86 | Z6: 丰台西山湖文苑北2-ZLH-LF-203-RRU03 | AA6: R8978 M1920A | AB6: =VLOOKUP(AA6,$AA$12:$AB$31,2,FALSE) -> 452984881 | AF6: =VLOOKUP(K6&#REF!,RRU频段及通道配置FDD!#REF!,2,0) -> #REF! | AG6: =VLOOKUP(#REF!,RRU频段及通道配置FDD!#REF!,20,0) -> #REF! | AQ6: 203 | AR6: 丰台西山湖文苑北2-ZLH-LF-203 | AS6: 167 | AT6: 4148 | AU6: 776 | AV6: TDD-F1 | AW6: =Y6 -> 86 | AX6: =_xlfn.XLOOKUP(AV6,$AV$12:$AV$24,$AX$12:$AX$24,,1,1) -> 39 | AY6: =_xlfn.XLOOKUP(AV6,$AV$12:$AV$24,$AY$12:$AY$24,,1,1) -> 1895 | AZ6: =_xlfn.XLOOKUP(AV6,$AV$12:$AV$24,$AX$12:$BD$24,,1,1)&" " | BA6: =_xlfn.XLOOKUP(AV6,$AV$12:$AV$24,$AX$12:$BD$24,,1,1) -> 20(100RB)[5] | BB6: =_xlfn.XLOOKUP(AV6,$AV$12:$AV$24,$AX$12:$BD$24,,1,1) -> 5 | BC6: =_xlfn.XLOOKUP(AV6,$AV$12:$AV$24,$BD$12:$BD$24,,0,1) -> 100[33] | BD6: =_xlfn.XLOOKUP(AV6,$AV$12:$AV$24,$BC$12:$BC$24,,1,1) -> 100 | BH6: 9 | BI6: 9:0 | BJ6: 15.2 | BK6: =VLOOKUP(AA:AA,RRU频段及通道配置FDD!A:P,16,0) -> 1;1;1;1;1;1;1;1;0;0;0;0;0;0;0;0;0;0;0;0;0;0;0;0;0;0;0;0;0;0;0;0;0;0;0;0;0;0;0;0;0;0;0;0;0;0;0;0;0;0;0;0;0;0;0;0;0;0;0;0;0;0;0;0 | BL6: =VLOOKUP(AA:AA,RRU频段及通道配置FDD!A:P,16,0)&" " -> 1;1;1;1;1;1;1;1;0;0;0;0;0;0;0;0;0;0;0;0;0;0;0;0;0;0;0;0;0;0;0;0;0;0;0;0;0;0;0;0;0;0;0;0;0;0;0;0;0;0;0;0;0;0;0;0;0;0;0;0;0;0;0;0 | BM6: =VLOOKUP(AA:AA,RRU频段及通道配置FDD!A:P,16,0)&" " -> 1;1;1;1;1;1;1;1;0;0;0;0;0;0;0;0;0;0;0;0;0;0;0;0;0;0;0;0;0;0;0;0;0;0;0;0;0;0;0;0;0;0;0;0;0;0;0;0;0;0;0;0;0;0;0;0;0;0;0;0;0;0;0;0 | BN6: =VLOOKUP(AA:AA,RRU频段及通道配置FDD!A:Q,17,0) -> 0;0;0;0;1;1;1;1;15;15;15;15;15;15;15;15;15;15;15;15;15;15;15;15;15;15;15;15;15;15;15;15;15;15;15;15;15;15;15;15;15;15;15;15;15;15;15;15;15;15;15;15;15;15;15;15;15;15;15;15;15;15;15;15 | BO6: 0 | BQ6: =VLOOKUP(AA:AA,RRU频段及通道配置FDD!A:T,19,0) -> 1 | BR6: slot13 | BT6: slot1 | BU6: CCC,0,0 | BV6: slot7
BR9: 槽位拓扑图
G10: 对应G列，下拉公式即可 | H10: 对应BBU1槽位，用公式引用后可以隐藏 | AB10: 下拉公式 | AD10: 一般一个站是2行（一行中移，一行广电） | AH10: 一般一个站是2行 | AX10: 根据开通频段对应配置，下拉公式即可 | BK10: 下拉公式
A11: 一共涉及几个小区 | B11: 一共两种扩容类型 | C11: 一共四种制式 | D11: MRSDR标识多个制式，LTE-FDD：单FDD，LTE-TDD：单TDD；根据开通制式填写 | E11: 根据模式类型对应填写 | F11: 根据开通制式填写 | G11: 根据模式标识对应填写 | H11: 主控板只能插1、2槽位 | J11: 交换板只能插3、4槽位，3-12槽位可以插基带班 | K11: 交换板只能插3、4槽位，3-12槽位可以插基带班 | L11: 3-12槽位可以插基带班 | M11: 3-12槽位可以插基地班 | N11: 3-12槽位可以插基地班 | O11: 3-12槽位可以插基地班 | P11: 3-12槽位可以插基地班 | Q11: 3-12槽位可以插基地班 | R11: 3-12槽位可以插基地班 | S11: 3-12槽位可以插基地班 | T11: 13、14槽位插环境监控板，现场无此单板，不用配置 | U11: 13、14槽位插环境监控板，现场无此单板，不用配置 | V11: 15槽位配置风扇板 | W11: 16、17槽位配置电源板（交流电源只支持配置一块，只能插16槽位） | X11: 16、17槽位配置电源板（交流电源只支持配置一块，只能插16槽位） | Y11: 工单中RRU编号 | Z11: 工单中RRU名称 | AA11: 工单中RRU型号 | AB11: 根据RRU型号对应填写 | AD11: 对应开通制式在对应列填写默认值，如果是FDD就填在fddServiceDscpMap，如果是：0;1;2;3;4;5;6;7;8;9;10;11;12;13;14;15;16;17;18;19;20;21;22;23;24;25;26;27;28;29;30;31;32;33;34;35;36;37;38;39;40;41;42;43;44;45;46;47;48;49;50;51;52;53;54;55;56;57;58;59;60;61;62;63 | AF11: 根据RRU型号填写对应RRU的通道，根据RRU频段及通道配置第3列填写 | AH11: 根据开通工单中传输数据分配填写 | AI11: 根据开站工单，基站ip地址 | AJ11: 根据传输分配IP掩码长度填写 | AK11: 根据开通工单维护网关、业务网关 | AO11: 1/2,1代表管理，2代表业务，不用修改 | AP11: 一平面传输配置0；三平面传输需配置24；工单看基站传输设备名是几平面，3开头还是1 | AQ11: 根据开通工单中E-UTRANNELL中扇区编号填写 | AR11: 根据开通工单中E-UTRANNELL中中文名称 | AS11: 根据开通工单中工单审核及规划数据分配中PCI填写 | AT11: 根据开通工单中工单审核及规划数据分配中TAC号填写 | AU11: 根据开通工单中工单审核及规划数据分配中PRACH填写 | AV11: 本次开站是FDD或者是TDD | AW11: 该小区对应的RRU编号 | BH11: 该小区对应哪一个基带板在哪一个槽位 | BI11: 填写格式：RRU对应基带板槽位号:0 | BJ11: 开站功率设置，E频12.2，其他频段15.2 | BK11: 根据“RRU频段及通道配置sheet”表里对应的RRU型号配置 | BL11: 根据“RRU频段及通道配置”表里对应的RRU型号配置 | BM11: 根据“RRU频段及通道配置”表里对应的RRU型号配置 | BN11: 根据“RRU频段及通道配置”表里对应的RRU型号配置 | BR11: 槽位号 | BS11: 设备型号
B12: 硬扩（有新增RRU） | C12: TDDtoTDD；FDDtoFDD | D12: MRSDR | E12: GFTLN_D_V5.60.20.00 | F12: 2;16;32;64 | G12: =VLOOKUP(F12,SCTP描述信息!D:E,2,0) -> UniRan 12.3(GFTLN V5.50.51) | AA12: R8854E S1800(A6A) | AB12: 1281 | AH12: 管理VLAN；对应moId：1 | AI12: 基站管理IP：1 | AJ12: 30位掩码：255.255.255.252 | AK12: 维护网关：1 | AV12: FDD900 | AX12: 8 | AY12: 894 | AZ12: 939 | BA12: 10(50RB)[3] | BB12: 10(50RB)[3] | BC12: 50 | BD12: 50[23]
B13: 软扩 | C13: TDDtoFDD；FDDtoTDD | D13: MRSDR | E13: GTDL_D_V5.60.20.00 | F13: 2;32 | G13: =VLOOKUP(F13,SCTP描述信息!D:E,2,0) -> UniRan 12.3(GTDL V5.50.51) | H13: CCE1,0,0 | I13: CCE1,0,0 | AA13: R8978 M1920A | AB13: 452984881 | AG13: TDD站点需要配置，FDD不用 | AH13: 业务VLAN；对应对应moId：2 | AI13: 基站业务IP：2 | AJ13: 29位掩码：255.255.255.248 | AK13: 业务网关：2 | AV13: FDD1800 | AX13: 3 | AY13: 1725 | AZ13: 1820 | BA13: 20(100RB)[5] | BB13: 20(100RB)[5] | BC13: 100 | BD13: 100[33] | BP13: TDD站点需要配置，FDD不用 | BQ13: TDD站点需要配置，FDD不用
D14: MRSDR | E14: FTL_D_V6.10.20.00 | F14: 16;32 | G14: =VLOOKUP(F14,SCTP描述信息!D:E,2,0) -> UniRan 12.4(LTE V5.50.51) | H14: CCE1A,0,0 | I14: CCE1A,0,0 | AA14: R8972E M1920A | AB14: 452984833 | AJ14: 26位掩码：255.255.255.192
D15: MRSDR | E15: GLN_D_V5.60.20.00 | F15: 2;16;64 | G15: =VLOOKUP(F15,SCTP描述信息!D:E,2,0) -> UniRan 12.3(GLN V5.50.51) | H15: CCF1,0,0 | I15: CCF1,0,0 | AA15: R8978 M1920 | AB15: 452984881 | BB15: 特殊子帧配置
D16: LTE-FDD | E16: L_D_V6.10.20.00 | F16: 16 | G16: =VLOOKUP(F16,SCTP描述信息!D:E,2,0) -> UniRan 12.4(LTE V5.50.51) | H16: CCC,0,0 | I16: CCC,0,0 | AA16: R8854 S1800(A4A) | AB16: 1281 | AV16: TDD-F1 | AX16: 39 | AY16: 1895 | BA16: 20(100RB)[5] | BB16: 5 | BC16: 100 | BD16: 100[33]
D17: LTE-TDD | E17: TDL_D_V6.10.20.00 | F17: 32 | G17: =VLOOKUP(F17,SCTP描述信息!D:E,2,0) -> UniRan 12.4(LTE V5.50.51) | H17: CCE1B,0,0 | I17: CCE1B,0,0 | AA17: R8852E S9000(A8A) | AB17: 20 | AV17: TDD-F2 | AX17: 39 | AY17: 1909.4 | BA17: 10(50RB)[3] | BB17: 5 | BC17: 50 | BD17: 50[23]
AA18: R8852E S1800(A8A) | AB18: 26 | AV18: TDD-A | AX18: 34 | AY18: 2017.5 | BA18: 15(75RB)[4] | BB18: 5 | BC18: 75 | BD18: 75[28]
AA19: R8852E S1800(A8A) | AB19: 1281 | AV19: TDD-E1 | AX19: 40 | AY19: 2330 | BA19: 20(100RB)[5] | BB19: 7 | BC19: 100 | BD19: 100[33] | BR19: 在对应的槽位填写设备信息：slotx 设备型号，具体1内容与现场一致
D20: MRSDR：多个制式开通 | E20: FTL_D_V6.10.20.00表示开通FDD+TDD | AA20: A9611A S26 | AB20: 100663425 | AV20: TDD-E2 | AX20: 40 | AY20: 2349.8 | BA20: 20(100RB)[5] | BB20: 7 | BC20: 100 | BD20: 100[33] | BR20: SlotX对应BBU的槽位，按照现场开通制式及单板槽位填写 主控板只能插到1/2槽位
D21: MRSDR：多个制式开通 | E21: GFTL_D_V5.50.10表示开通GSM+FDD+TDD | AA21: R8968E M1920 | AB21: 452984881 | AV21: TDD-E3 | AX21: 40 | AY21: 2364.2 | BA21: 10(50RB)[3] | BB21: 7 | BC21: 50 | BD21: 50[23] | BR21: FS、CR0等交换板只能插到3/4槽位，3-12槽位都支持基带板
D22: MRSDR：多个制式开通 | E22: LN_D_V6.10.20.00表示开通FDD+NB | AA22: R8928FA | AB22: 452984833 | AV22: TDD-D3 | AX22: 41 | AY22: 2624.6 | BA22: 20(100RB)[5] | BB22: 7 | BC22: 100 | BD22: 100[33] | BR22: 风扇只能插到15槽位，直流电源PM可以插到16/17槽位，交流电源PMAC只能插16槽位
D23: LTE-FDD：单FDD | E23: L_D_V6.10.20.00表示开通FDD | AA23: R8852E S9000(A8A) | AB23: 7 | AV23: TDD-D7 | AX23: 41 | AY23: 2644.4 | BA23: 20(100RB)[5] | BB23: 7 | BC23: 100 | BD23: 100[33]
D24: LTE-TDD：单TDD | E24: TDL_D_V6.10.20.00表示开通TDD | AA24: R8978 S2600W | AB24: 100663297 | AV24: TDD-D8 | AX24: 41 | AY24: 2664.2 | BA24: 20(100RB)[5] | BB24: 7 | BC24: 100 | BD24: 100[33] | BR24: 主控板配置，功能模式和主控单板工作模式都配置0，主控板只能插1、2槽位
AA25: R8862A S1800(B6B) | AB25: 1281 | BR25: 单板类型，开通的制式，根据对应RRU对应相应的功能模式，交换板只能插3、4槽位，3-12槽位可以插基带板
AA26: R8972 M1920 | AB26: 452984881 | BR26: 13、14槽位插环境监控板，现场无此单板，不用配置
AA27: R8972E M192023 | AB27: 452984833 | BR27: 16、17槽位配置电源板（交流电源只支持配置一块，只能插16槽位）
AA28: R8854 S1800(A4A) | AB28: 20
AA29: R8968i M1920 | AB29: 452984833 | BR29: 主控板：单板类型，功能模式，主控单板工作模式 | BV29: 基带板：单板类型，无线制式，功能模式
A30: 说明：红色对应列填写行数与RRU数一致，蓝色对应行数与小区数一致，无颜色一行即可，有特殊行数会对应列有提示。紫色对应列为公式。填写完此表后复制数据到RANCM-sdrPlan中，粘贴转换为数值。 | AA30: R8139 M90182326 | AB30: 1090519041 | BR30: CCE1,0,0 | BV30: BPP1,16,4104
AA31: R8854E S1800(A6A) | AB31: 26 | BR31: CCE1A,0,0 | BV31: BPN2,16,4104
BR32: CCF1,0,0 | BV32: BPN2,16;64,20490
BR33: CCC,0,0 | BV33: BPP1,64,16385
BR34: CCE1B,0,0 | BV34: BPP1,16;64,20491
BV35: BPQ3B,32,100671513
BV36: BPN2,64,16385
BV37: BPN2,32,100671497
BV38: BPQ2,16,4104
BV39: BPL1,16,3,1
BV40: BPQ2,32,100671497
BV41: UBPG3,2,0
BV42: BPQ0,32,100671497
...

Sheet RRU
A1: BBU机框slot号 | B1: 3 | C1: 3 | D1: 3 | E1: 3 | F1: 3 | G1: 3 | H1: 4 | I1: 4 | J1: 4 | K1: 4 | L1: 4 | M1: 4 | N1: 5 | O1: 5 | P1: 5 | Q1: 5 | R1: 5 | S1: 5 | T1: 6 | U1: 6 | V1: 6 | W1: 6 | X1: 6 | Y1: 6 | Z1: 7 | AA1: 7 | AB1: 7 | AC1: 7 | AD1: 7 | AE1: 7 | AF1: 8 | AG1: 8 | AH1: 8 | AI1: 8 | AJ1: 8 | AK1: 8 | AL1: 9 | AM1: 9 | AN1: 9 | AO1: 9 | AP1: 9 | AQ1: 9 | AR1: 10 | AS1: 10 | AT1: 10 | AU1: 10 | AV1: 10 | AW1: 10 | AX1: 11 | AY1: 11 | AZ1: 11 | BA1: 11 | BB1: 11 | BC1: 11 | BD1: 12 | BE1: 12 | BF1: 12 | BG1: 12 | BH1: 12 | BI1: 12
A2: 基带板端口号 | B2: 5 | C2: 4 | D2: 3 | E2: 2 | F2: 1 | G2: 0 | H2: 5 | I2: 4 | J2: 3 | K2: 2 | L2: 1 | M2: 0 | N2: 5 | O2: 4 | P2: 3 | Q2: 2 | R2: 1 | S2: 0 | T2: 5 | U2: 4 | V2: 3 | W2: 2 | X2: 1 | Y2: 0 | Z2: 5 | AA2: 4 | AB2: 3 | AC2: 2 | AD2: 1 | AE2: 0 | AF2: 5 | AG2: 4 | AH2: 3 | AI2: 2 | AJ2: 1 | AK2: 0 | AL2: 5 | AM2: 4 | AN2: 3 | AO2: 2 | AP2: 1 | AQ2: 0 | AR2: 5 | AS2: 4 | AT2: 3 | AU2: 2 | AV2: 1 | AW2: 0 | AX2: 5 | AY2: 4 | AZ2: 3 | BA2: 2 | BB2: 1 | BC2: 0 | BD2: 5 | BE2: 4 | BF2: 3 | BG2: 2 | BH2: 1 | BI2: 0
A3: RRU编号 | BG3: 86 | BH3: 85 | BI3: 84
A16: 此图为RRU连接拓扑图，包含RRU与基带板、RRU与RRU之间的光口连接关系。 RRU编号在开站工单中确定，连接拓扑结构与前台实际连接一致。

Sheet 基带板主控板说明
A2: 主控板配置，功能模式和主控单板工作模式都配置0 | B2: 基带板单板类型，开通的制式，根据对应RRU对应相应的功能模式
A3: 单板类型，功能模式，主控单板工作模式 | B3: 单板类型，无线制式，功能模式 | C3: RU类型 | D3: RRU无线制式 | E3: RRU单板功能模式
A4: CCE1,0,0 | B4: BPP1,16,4104 | C4: R8854E S1800(A6A) | D4: 16 | E4: 1281
A5: CCE1A,0,0 | B5: BPN2,16,4104 | C5: R8978 M1920A | D5: 32 | E5: 452984881
A6: CCF1,0,0 | B6: BPN2,16;64,20490 | C6: R8972E M1920A | D6: 32 | E6: 452984833
A7: CCC,0,0 | B7: BPP1,64,16385 | C7: R8978 M1920 | D7: 32 | E7: 452984881
A8: CCE1B,0,0 | B8: BPP1,16;64,20491 | C8: R8854 S1800(A4A) | D8: 16 | E8: 1281
B9: BPQ3B,32,100671513 | C9: R8852E S9000(A8A) | D9: 2;16;64 | E9: 20
B10: BPN2,64,16385 | C10: R8852E S1800(A8A) | D10: 2;16 | E10: 26
B11: BPN2,32,100671497 | C11: R8852E S1800(A8A) | D11: 16 | E11: 1281
B12: BPQ2,16,4104 | C12: A9611A S26 | D12: 32 | E12: 1073741825
B13: BPL1,16,3,1 | C13: R8968E M1920 | D13: 32 | E13: 452984881
B14: BPQ2,32,100671497 | C14: R8928FA | D14: 32 | E14: 452984833
B15: UBPG3,2,0 | C15: R8852E S9000(A8A) | D15: 64 | E15: 7
B16: BPQ0,32,100671497 | C16: R8978 S2600W | D16: 32 | E16: 100663297
B17: FS,0,1,7 | C17: R8862A S1800(B6B) | D17: 16 | E17: 1281
B18: CR0,0,100675585 | C18: R8972 M1920 | D18: 32 | E18: 452984881
B19: BPN0,32,100671497 | C19: R8968 S2600 | D19: 32 | E19: 100663297
B20: FS,0,1,8 | C20: R8972E M192023 | D20: 32 | E20: 452984833
... B23: CR0,0,104869889 | C23: PB1124F | D23: 0 | E23: 11
C24: R8139 M90182326 | D24: 16;32 | E24: 1090519041
C25: R8854E S1800(A6A) | D25: 2;16 | E25: 26
C26: R8852E S1800(A8A) | D26: 2;16;64 | E26: 20
C27: R8852E S9000(A8A) | D27: 16 | E27: 1281
C28: R8862A S1800(A6A) | D28: 16 | E28: 1281
C29: R8862A S1800(B6A) | D29: 16 | E29: 1281
C30: R8972E M1920 | D30: 32 | E30: 452984833
C31: A8724 M192026(A2B) | D31: 32 | E31: 100663297
C32: R8972E S2600W | D32: 32 | E32: 100663297
C33: R8972E S2600 | D33: 32 | E33: 100663297
C34: R8854E S1800(A6A) | D34: 2;16;64 | E34: 20
C35: R8502 S2300 | D35: 32 | E35: 100663297
... C50: PB1124F | D50: 0 | E50: 12

Sheet RRU频段及通道配置TDD
A1: RRU型号 | B1: 支持频段 | C1: IrAntGroup-连接的发射设备 | D1: IrAntGroup-使用的天线属性 | E1: Cell4GTDD-上行激活天线位图(小区复位生效) | F1: Cell4GTDD-天线端口与天线通道的映射关系 | G1: 开通默认配置功率 | H1: 小区模式（小区复位生效）
A2: A8712 M192026 | B2: F1/F2/A | C2: 51:1&51:2 | D2: 202 | E2: 1;1;0;0;0;0;0;0;0;0;0;0;0;0;0;0;0;0;0;0;0;0;0;0;0;0;0;0;0;0;0;0;0;0;0;0;0;0;0;0;0;0;0;0;0;0;0;0;0;0;0;0;0;0;0;0;0;0;0;0;0;0;0;0 | F2: 0;1;15;15;15;15;15;15;15;15;15;15;15;15;15;15;15;15;15;15;15;15;15;15;15;15;15;15;15;15;15;15;15;15;15;15;15;15;15;15;15;15;15;15;15;15;15;15;15;15;15;15;15;15;15;15;15;15;15;15;15;15;15;15 | G2: 12.2 | H2: 0
A3: A8712 M192026 | B3: D1/D2/D3 | C3: 51:3&51:4 | D3: 202 | E3: 0;0;1;1;0;0;0;0;0;0;0;0;0;0;0;0;0;0;0;0;0;0;0;0;0;0;0;0;0;0;0;0;0;0;0;0;0;0;0;0;0;0;0;0;0;0;0;0;0;0;0;0;0;0;0;0;0;0;0;0;0;0;0;0 | F3: 15;15;0;1;15;15;15;15;15;15;15;15;15;15;15;15;15;15;15;15;15;15;15;15;15;15;15;15;15;15;15;15;15;15;15;15;15;15;15;15;15;15;15;15;15;15;15;15;15;15;15;15;15;15;15;15;15;15;15;15;15;15;15;15 | G3: 12.2 | H3: 0
A4: A8724 M192026 | B4: F1/F2/A | C4: 51:1&51:2&51:3&51:4 | D4: 351 | E4: 1;1;1;1;0;0;0;0;0;0;0;0;0;0;0;0;0;0;0;0;0;0;0;0;0;0;0;0;0;0;0;0;0;0;0;0;0;0;0;0;0;0;0;0;0;0;0;0;0;0;0;0;0;0;0;0;0;0;0;0;0;0;0;0 | F4: 0;0;1;1;15;15;15;15;15;15;15;15;15;15;15;15;15;15;15;15;15;15;15;15;15;15;15;15;15;15;15;15;15;15;15;15;15;15;15;15;15;15;15;15;15;15;15;15;15;15;15;15;15;15;15;15;15;15;15;15;15;15;15;15 | G4: 12.2 | H4: 1
A5: A8724 M192026 | B5: D3/D7/D8 | C5: 51:5&51:6&51:7&51:8 | D5: 351 | E5: 0;0;0;0;1;1;1;1;0;0;0;0;0;0;0;0;0;0;0;0;0;0;0;0;0;0;0;0;0;0;0;0;0;0;0;0;0;0;0;0;0;0;0;0;0;0;0;0;0;0;0;0;0;0;0;0;0;0;0;0;0;0;0;0 | F5: 15;15;15;15;0;0;1;1;15;15;15;15;15;15;15;15;15;15;15;15;15;15;15;15;15;15;15;15;15;15;15;15;15;15;15;15;15;15;15;15;15;15;15;15;15;15;15;15;15;15;15;15;15;15;15;15;15;15;15;15;15;15;15;15 | G5: 12.2 | H5: 1
A6: R8502 S2300 | B6: E1/E2/E3 | C6: 51:2 | D6: 201 | E6: 0;1;0;0;0;0;0;0;0;0;0;0;0;0;0;0;0;0;0;0;0;0;0;0;0;0;0;0;0;0;0;0;0;0;0;0;0;0;0;0;0;0;0;0;0;0;0;0;0;0;0;0;0;0;0;0;0;0;0;0;0;0;0;0 | F6: 15;0;15;15;15;15;15;15;15;15;15;15;15;15;15;15;15;15;15;15;15;15;15;15;15;15;15;15;15;15;15;15;15;15;15;15;15;15;15;15;15;15;15;15;15;15;15;15;15;15;15;15;15;15;15;15;15;15;15;15;15;15;15;15 | G6: 12.2 | H6: 0
A7: R8502 S2600 | B7: D1/D2/D3 | C7: 51:1&51:2 | D7: 双通道配置202；单通道配置201 | E7: 1;1;0;0;0;0;0;0;0;0;0;0;0;0;0;0;0;0;0;0;0;0;0;0;0;0;0;0;0;0;0;0;0;0;0;0;0;0;0;0;0;0;0;0;0;0;0;0;0;0;0;0;0;0;0;0;0;0;0;0;0;0;0;0 | F7: 0;1;15;15;15;15;15;15;15;15;15;15;15;15;15;15;15;15;15;15;15;15;15;15;15;15;15;15;15;15;15;15;15;15;15;15;15;15;15;15;15;15;15;15;15;15;15;15;15;15;15;15;15;15;15;15;15;15;15;15;15;15;15;15 | G7: 12.2 | H7: 0
A8: R8502E S2600 | B8: D1/D2/D3 | C8: 51:1&51:2 | D8: 双通道配置202；单通道配置201 | E8: 1;1;0;0;0;0;0;0;0;0;0;0;0;0;0;0;0;0;0;0;0;0;0;0;0;0;0;0;0;0;0;0;0;0;0;0;0;0;0;0;0;0;0;0;0;0;0;0;0;0;0;0;0;0;0;0;0;0;0;0;0;0;0;0 | F8: 0;1;15;15;15;15;15;15;15;15;15;15;15;15;15;15;15;15;15;15;15;15;15;15;15;15;15;15;15;15;15;15;15;15;15;15;15;15;15;15;15;15;15;15;15;15;15;15;15;15;15;15;15;15;15;15;15;15;15;15;15;15;15;15 | G8: 12.2 | H8: 0
A9: R8968E M1920 | B9: F1/F2/A | C9: 51:1&51:2&51:3&51:4&51:5&51:6&51:7&51:8 | D9: 16 | E9: 1;1;1;1;1;1;1;1;0;0;0;0;0;0;0;0;0;0;0;0;0;0;0;0;0;0;0;0;0;0;0;0;0;0;0;0;0;0;0;0;0;0;0;0;0;0;0;0;0;0;0;0;0;0;0;0;0;0;0;0;0;0;0;0 | F9: 0;0;0;0;1;1;1;1;15;15;15;15;15;15;15;15;15;15;15;15;15;15;15;15;15;15;15;15;15;15;15;15;15;15;15;15;15;15;15;15;15;15;15;15;15;15;15;15;15;15;15;15;15;15;15;15;15;15;15;15;15;15;15;15 | G9: 15.2 | H9: 1
A10: R8972 M1920 | B10: F1/F2/A | C10: 51:1&51:2 | D10: 双通道配置202；单通道配置201 | E10: 1;1;0;0;0;0;0;0;0;0;0;0;0;0;0;0;0;0;0;0;0;0;0;0;0;0;0;0;0;0;0;0;0;0;0;0;0;0;0;0;0;0;0;0;0;0;0;0;0;0;0;0;0;0;0;0;0;0;0;0;0;0;0;0 | F10: 0;1;15;15;15;15;15;15;15;15;15;15;15;15;15;15;15;15;15;15;15;15;15;15;15;15;15;15;15;15;15;15;15;15;15;15;15;15;15;15;15;15;15;15;15;15;15;15;15;15;15;15;15;15;15;15;15;15;15;15;15;15;15;15 | G10: 15.2 | H10: 0
A11: R8972 M192023 | B11: F1/F2/A | C11: 51:1 | D11: 201 | E11: 1;0;0;0;0;0;0;0;0;0;0;0;0;0;0;0;0;0;0;0;0;0;0;0;0;0;0;0;0;0;0;0;0;0;0;0;0;0;0;0;0;0;0;0;0;0;0;0;0;0;0;0;0;0;0;0;0;0;0;0;0;0;0;0 | F11: 0;15;15;15;15;15;15;15;15;15;15;15;15;15;15;15;15;15;15;15;15;15;15;15;15;15;15;15;15;15;15;15;15;15;15;15;15;15;15;15;15;15;15;15;15;15;15;15;15;15;15;15;15;15;15;15;15;15;15;15;15;15;15;15 | G11: 15.2 | H11: 0
A12: R8972 M192023 | B12: E1/E2/E3 | C12: 51:2 | D12: 201 | E12: 0;1;0;0;0;0;0;0;0;0;0;0;0;0;0;0;0;0;0;0;0;0;0;0;0;0;0;0;0;0;0;0;0;0;0;0;0;0;0;0;0;0;0;0;0;0;0;0;0;0;0;0;0;0;0;0;0;0;0;0;0;0;0;0 | F12: 15;0;15;15;15;15;15;15;15;15;15;15;15;15;15;15;15;15;15;15;15;15;15;15;15;15;15;15;15;15;15;15;15;15;15;15;15;15;15;15;15;15;15;15;15;15;15;15;15;15;15;15;15;15;15;15;15;15;15;15;15;15;15;15 | G12: 15.2 | H12: 0
A13: R8972 S2300 | B13: E1/E2/E3 | C13: 51:1&51:2 | D13: 双通道配置202；单通道配置201 | E13: 1;1;0;0;0;0;0;0;0;0;0;0;0;0;0;0;0;0;0;0;0;0;0;0;0;0;0;0;0;0;0;0;0;0;0;0;0;0;0;0;0;0;0;0;0;0;0;0;0;0;0;0;0;0;0;0;0;0;0;0;0;0;0;0 | F13: 0;1;15;15;15;15;15;15;15;15;15;15;15;15;15;15;15;15;15;15;15;15;15;15;15;15;15;15;15;15;15;15;15;15;15;15;15;15;15;15;15;15;15;15;15;15;15;15;15;15;15;15;15;15;15;15;15;15;15;15;15;15;15;15 | G13: 15.2 | H13: 0
A14: R8972E M1920 | B14: F1/F2/A | C14: 51:1&51:2 | D14: 双通道配置202；单通道配置201 | E14: 1;1;0;0;0;0;0;0;0;0;0;0;0;0;0;0;0;0;0;0;0;0;0;0;0;0;0;0;0;0;0;0;0;0;0;0;0;0;0;0;0;0;0;0;0;0;0;0;0;0;0;0;0;0;0;0;0;0;0;0;0;0;0;0 | F14: 0;1;15;15;15;15;15;15;15;15;15;15;15;15;15;15;15;15;15;15;15;15;15;15;15;15;15;15;15;15;15;15;15;15;15;15;15;15;15;15;15;15;15;15;15;15;15;15;15;15;15;15;15;15;15;15;15;15;15;15;15;15;15;15 | G14: 15.2 | H14: 0
A15: R8972E M192023 | B15: F1/F2/A | C15: 51:1 | D15: 201 | E15: 1;0;0;0;0;0;0;0;0;0;0;0;0;0;0;0;0;0;0;0;0;0;0;0;0;0;0;0;0;0;0;0;0;0;0;0;0;0;0;0;0;0;0;0;0;0;0;0;0;0;0;0;0;0;0;0;0;0;0;0;0;0;0;0 | F15: 0;15;15;15;15;15;15;15;15;15;15;15;15;15;15;15;15;15;15;15;15;15;15;15;15;15;15;15;15;15;15;15;15;15;15;15;15;15;15;15;15;15;15;15;15;15;15;15;15;15;15;15;15;15;15;15;15;15;15;15;15;15;15;15 | G15: 15.2 | H15: 0
A16: R8972E M192023 | B16: E1/E2/E3 | C16: 51:2 | D16: 201 | E16: 0;1;0;0;0;0;0;0;0;0;0;0;0;0;0;0;0;0;0;0;0;0;0;0;0;0;0;0;0;0;0;0;0;0;0;0;0;0;0;0;0;0;0;0;0;0;0;0;0;0;0;0;0;0;0;0;0;0;0;0;0;0;0;0 | F16: 15;0;15;15;15;15;15;15;15;15;15;15;15;15;15;15;15;15;15;15;15;15;15;15;15;15;15;15;15;15;15;15;15;15;15;15;15;15;15;15;15;15;15;15;15;15;15;15;15;15;15;15;15;15;15;15;15;15;15;15;15;15;15;15 | G16: 15.2 | H16: 0
A17: R8972E M192023A | B17: F1/F2/A | C17: 51:1 | D17: 201 | E17: 1;0;0;0;0;0;0;0;0;0;0;0;0;0;0;0;0;0;0;0;0;0;0;0;0;0;0;0;0;0;0;0;0;0;0;0;0;0;0;0;0;0;0;0;0;0;0;0;0;0;0;0;0;0;0;0;0;0;0;0;0;0;0;0 | F17: 0;15;15;15;15;15;15;15;15;15;15;15;15;15;15;15;15;15;15;15;15;15;15;15;15;15;15;15;15;15;15;15;15;15;15;15;15;15;15;15;15;15;15;15;15;15;15;15;15;15;15;15;15;15;15;15;15;15;15;15;15;15;15;15 | G17: 15.2 | H17: 0
A18: R8972E M192023A | B18: E1/E2 | C18: 51:2 | D18: 201 | E18: 0;1;0;0;0;0;0;0;0;0;0;0;0;0;0;0;0;0;0;0;0;0;0;0;0;0;0;0;0;0;0;0;0;0;0;0;0;0;0;0;0;0;0;0;0;0;0;0;0;0;0;0;0;0;0;0;0;0;0;0;0;0;0;0 | F18: 15;0;15;15;15;15;15;15;15;15;15;15;15;15;15;15;15;15;15;15;15;15;15;15;15;15;15;15;15;15;15;15;15;15;15;15;15;15;15;15;15;15;15;15;15;15;15;15;15;15;15;15;15;15;15;15;15;15;15;15;15;15;15;15 | G18: 15.2 | H18: 0
A19: R8972E M1920A | B19: F1/F2/A | C19: 51:1&51:2 | D19: 双通道配置202；单通道配置201 | E19: 1;1;0;0;0;0;0;0;0;0;0;0;0;0;0;0;0;0;0;0;0;0;0;0;0;0;0;0;0;0;0;0;0;0;0;0;0;0;0;0;0;0;0;0;0;0;0;0;0;0;0;0;0;0;0;0;0;0;0;0;0;0;0;0 | F19: 0;1;15;15;15;15;15;15;15;15;15;15;15;15;15;15;15;15;15;15;15;15;15;15;15;15;15;15;15;15;15;15;15;15;15;15;15;15;15;15;15;15;15;15;15;15;15;15;15;15;15;15;15;15;15;15;15;15;15;15;15;15;15;15 | G19: 15.2 | H19: 0
A20: R8972E S2300 | B20: E1/E2/E3 | C20: 51:1&51:2 | D20: 双通道配置202；单通道配置201 | E20: 1;1;0;0;0;0;0;0;0;0;0;0;0;0;0;0;0;0;0;0;0;0;0;0;0;0;0;0;0;0;0;0;0;0;0;0;0;0;0;0;0;0;0;0;0;0;0;0;0;0;0;0;0;0;0;0;0;0;0;0;0;0;0;0 | F20: 0;1;15;15;15;15;15;15;15;15;15;15;15;15;15;15;15;15;15;15;15;15;15;15;15;15;15;15;15;15;15;15;15;15;15;15;15;15;15;15;15;15;15;15;15;15;15;15;15;15;15;15;15;15;15;15;15;15;15;15;15;15;15;15 | G20: 15.2 | H20: 0
A21: R8972E S2300W | B21: E1/E2/E3 | C21: 51:1&51:2 | D21: 双通道配置202；单通道配置201 | E21: 1;1;0;0;0;0;0;0;0;0;0;0;0;0;0;0;0;0;0;0;0;0;0;0;0;0;0;0;0;0;0;0;0;0;0;0;0;0;0;0;0;0;0;0;0;0;0;0;0;0;0;0;0;0;0;0;0;0;0;0;0;0;0;0 | F21: 0;1;15;15;15;15;15;15;15;15;15;15;15;15;15;15;15;15;15;15;15;15;15;15;15;15;15;15;15;15;15;15;15;15;15;15;15;15;15;15;15;15;15;15;15;15;15;15;15;15;15;15;15;15;15;15;15;15;15;15;15;15;15;15 | G21: 15.2 | H21: 0
A22: R8972E S2600W | B22: D1/D2/D3 | C22: 51:1&51:2 | D22: 双通道配置202；单通道配置201 | E22: 1;1;0;0;0;0;0;0;0;0;0;0;0;0;0;0;0;0;0;0;0;0;0;0;0;0;0;0;0;0;0;0;0;0;0;0;0;0;0;0;0;0;0;0;0;0;0;0;0;0;0;0;0;0;0;0;0;0;0;0;0;0;0;0 | F22: 0;1;15;15;15;15;15;15;15;15;15;15;15;15;15;15;15;15;15;15;15;15;15;15;15;15;15;15;15;15;15;15;15;15;15;15;15;15;15;15;15;15;15;15;15;15;15;15;15;15;15;15;15;15;15;15;15;15;15;15;15;15;15;15 | G22: 15.2 | H22: 0
A23: R8978 M1920 | B23: F1/F2/A | C23: 51:1&51:2&51:3&51:4&51:5&51:6&51:7&51:8 | D23: 16 | E23: 1;1;1;1;1;1;1;1;0;0;0;0;0;0;0;0;0;0;0;0;0;0;0;0;0;0;0;0;0;0;0;0;0;0;0;0;0;0;0;0;0;0;0;0;0;0;0;0;0;0;0;0;0;0;0;0;0;0;0;0;0;0;0;0 | F23: 0;0;0;0;1;1;1;1;15;15;15;15;15;15;15;15;15;15;15;15;15;15;15;15;15;15;15;15;15;15;15;15;15;15;15;15;15;15;15;15;15;15;15;15;15;15;15;15;15;15;15;15;15;15;15;15;15;15;15;15;15;15;15;15 | G23: 15.2 | H23: 1
A24: R8978 M1920A | B24: F1/F2/A | C24: 51:1&51:2&51:3&51:4&51:5&51:6&51:7&51:8 | D24: 16 | E24: 1;1;1;1;1;1;1;1;0;0;0;0;0;0;0;0;0;0;0;0;0;0;0;0;0;0;0;0;0;0;0;0;0;0;0;0;0;0;0;0;0;0;0;0;0;0;0;0;0;0;0;0;0;0;0;0;0;0;0;0;0;0;0;0 | F24: 0;0;0;0;1;1;1;1;15;15;15;15;15;15;15;15;15;15;15;15;15;15;15;15;15;15;15;15;15;15;15;15;15;15;15;15;15;15;15;15;15;15;15;15;15;15;15;15;15;15;15;15;15;15;15;15;15;15;15;15;15;15;15;15 | G24: 15.2 | H24: 1
A25: R8978 S2600W | B25: D1/D2/D3 | C25: 51:1&51:2&51:3&51:4&51:5&51:6&51:7&51:8 | D25: 16 | E25: 1;1;1;1;1;1;1;1;0;0;0;0;0;0;0;0;0;0;0;0;0;0;0;0;0;0;0;0;0;0;0;0;0;0;0;0;0;0;0;0;0;0;0;0;0;0;0;0;0;0;0;0;0;0;0;0;0;0;0;0;0;0;0;0 | F25: 0;0;0;0;1;1;1;1;15;15;15;15;15;15;15;15;15;15;15;15;15;15;15;15;15;15;15;15;15;15;15;15;15;15;15;15;15;15;15;15;15;15;15;15;15;15;15;15;15;15;15;15;15;15;15;15;15;15;15;15;15;15;15;15 | G25: 15.2 | H25: 1
A26: R8984 M192026 | B26: F1/F2/A | C26: 51:1&51:2 | D26: 252 | E26: 1;1;0;0;0;0;0;0;0;0;0;0;0;0;0;0;0;0;0;0;0;0;0;0;0;0;0;0;0;0;0;0;0;0;0;0;0;0;0;0;0;0;0;0;0;0;0;0;0;0;0;0;0;0;0;0;0;0;0;0;0;0;0;0 | F26: 0;1;15;15;15;15;15;15;15;15;15;15;15;15;15;15;15;15;15;15;15;15;15;15;15;15;15;15;15;15;15;15;15;15;15;15;15;15;15;15;15;15;15;15;15;15;15;15;15;15;15;15;15;15;15;15;15;15;15;15;15;15;15;15 | G26: 15.2 | H26: 1
A27: R8984 M192026 | B27: D1/D2/D3 | C27: 51:3&51:4 | D27: 252 | E27: 0;0;1;1;0;0;0;0;0;0;0;0;0;0;0;0;0;0;0;0;0;0;0;0;0;0;0;0;0;0;0;0;0;0;0;0;0;0;0;0;0;0;0;0;0;0;0;0;0;0;0;0;0;0;0;0;0;0;0;0;0;0;0;0 | F27: 15;15;0;1;15;15;15;15;15;15;15;15;15;15;15;15;15;15;15;15;15;15;15;15;15;15;15;15;15;15;15;15;15;15;15;15;15;15;15;15;15;15;15;15;15;15;15;15;15;15;15;15;15;15;15;15;15;15;15;15;15;15;15;15 | G27: 15.2 | H27: 1

Sheet RRU频段及通道配置FDD
A1: RRU型号 | B1: 支持频段 | C1: RRU编号 | E1: 1通道 | F1: 2通道 | G1: 3通道 | H1: 4通道 | O1: Cell4GFDD-射频口对象（依RRU编号51为例） | P1: Cell4GFDD-下行天线配置映射位图（小区复位生效）/上行天线配置映射位图(小区复位生效)/上行激活天线位图(小区复位生效) | Q1: Cell4GFDD-天线端口与天线通道的映射关系 | R1: 开通默认配置功率
A2: R8852E S9000(A8A) | B2: 900 | C2: =填表说明!$AW$4 -> 84 | D2: & | E2: :1 | F2: :2 | G2: :3 | H2: :4 | M2: =A2&C2 -> R8852E S9000(A8A)84 | N2: =C2&E2&";"&C2&H2 -> 84:1;84:4 | P2: 1;0;0;1;0;0;0;0;0;0;0;0;0;0;0;0;0;0;0;0;0;0;0;0;0;0;0;0;0;0;0;0;0;0;0;0;0;0;0;0;0;0;0;0;0;0;0;0;0;0;0;0;0;0;0;0;0;0;0;0;0;0;0;0 | Q2: 0;15;15;1;15;15;15;15;15;15;15;15;15;15;15;15;15;15;15;15;15;15;15;15;15;15;15;15;15;15;15;15;15;15;15;15;15;15;15;15;15;15;15;15;15;15;15;15;15;15;15;15;15;15;15;15;15;15;15;15;15;15;15;15 | R2: 15.2
A3: R8852E S1800(A8A) | B3: 1800 | C3: =填表说明!$AW$4 -> 84 | D3: & | E3: :1 | F3: :2 | G3: :3 | H3: :4 | M3: =A3&C3 -> R8852E S1800(A8A)84 | N3: =C3&E3&";"&C3&H3 -> 84:1;84:4 | P3: 1;0;0;1;0;0;0;0;0;0;0;0;0;0;0;0;0;0;0;0;0;0;0;0;0;0;0;0;0;0;0;0;0;0;0;0;0;0;0;0;0;0;0;0;0;0;0;0;0;0;0;0;0;0;0;0;0;0;0;0;0;0;0;0 | Q3: 0;15;15;1;15;15;15;15;15;15;15;15;15;15;15;15;15;15;15;15;15;15;15;15;15;15;15;15;15;15;15;15;15;15;15;15;15;15;15;15;15;15;15;15;15;15;15;15;15;15;15;15;15;15;15;15;15;15;15;15;15;15;15;15 | R3: 15.2
A4: R8854E S1800(A6A) | B4: 1800 | C4: =填表说明!$AW$4 -> 84 | D4: & | E4: :1 | F4: :2 | G4: :3 | H4: :4 | M4: =A4&C4 -> R8854E S1800(A6A)84 | N4: =C4&E4&";"&C4&F4&";"&C4&G4&";"&C4&H4 -> 84:1;84:2;84:3;84:4 | P4: 1;1;1;1;0;0;0;0;0;0;0;0;0;0;0;0;0;0;0;0;0;0;0;0;0;0;0;0;0;0;0;0;0;0;0;0;0;0;0;0;0;0;0;0;0;0;0;0;0;0;0;0;0;0;0;0;0;0;0;0;0;0;0;0 | Q4: 0;1;2;3;15;15;15;15;15;15;15;15;15;15;15;15;15;15;15;15;15;15;15;15;15;15;15;15;15;15;15;15;15;15;15;15;15;15;15;15;15;15;15;15;15;15;15;15;15;15;15;15;15;15;15;15;15;15;15;15;15;15;15;15 | R4: 15.2
A5: R8862A S1800(B6A) | B5: 1800 | C5: =填表说明!$AW$4 -> 84 | D5: & | E5: :1 | F5: :2 | G5: :3 | H5: :4 | M5: =A5&C5 -> R8862A S1800(B6A)84 | N5: =C5&E5&";"&C5&H5 -> 84:1;84:4 | P5: 1;0;0;1;0;0;0;0;0;0;0;0;0;0;0;0;0;0;0;0;0;0;0;0;0;0;0;0;0;0;0;0;0;0;0;0;0;0;0;0;0;0;0;0;0;0;0;0;0;0;0;0;0;0;0;0;0;0;0;0;0;0;0;0 | Q5: 0;15;15;1;15;15;15;15;15;15;15;15;15;15;15;15;15;15;15;15;15;15;15;15;15;15;15;15;15;15;15;15;15;15;15;15;15;15;15;15;15;15;15;15;15;15;15;15;15;15;15;15;15;15;15;15;15;15;15;15;15;15;15;15 | R5: 15.2
A6: R8854 S1800(A4A) | B6: 1800 | C6: =填表说明!$AW$4 -> 84 | D6: & | E6: :1 | F6: :2 | G6: :3 | H6: :4 | M6: =A6&C6 -> R8854 S1800(A4A)84 | N6: =C6&E6&";"&C6&F6&";"&C6&G6&";"&C6&H6 -> 84:1;84:2;84:3;84:4 | P6: 1;1;1;1;0;0;0;0;0;0;0;0;0;0;0;0;0;0;0;0;0;0;0;0;0;0;0;0;0;0;0;0;0;0;0;0;0;0;0;0;0;0;0;0;0;0;0;0;0;0;0;0;0;0;0;0;0;0;0;0;0;0;0;0 | Q6: 0;1;2;3;15;15;15;15;15;15;15;15;15;15;15;15;15;15;15;15;15;15;15;15;15;15;15;15;15;15;15;15;15;15;15;15;15;15;15;15;15;15;15;15;15;15;15;15;15;15;15;15;15;15;15;15;15;15;15;15;15;15;15;15 | R6: 15.2
A7: R8862A S1800(B6B) | B7: 1800 | C7: =填表说明!$AW$4 -> 84 | D7: & | E7: :1 | F7: :2 | G7: :3 | H7: :4 | M7: =A7&C7 -> R8862A S1800(B6B)84 | N7: =C7&E7&";"&C7&H7 -> 84:1;84:4 | P7: 1;0;0;1;0;0;0;0;0;0;0;0;0;0;0;0;0;0;0;0;0;0;0;0;0;0;0;0;0;0;0;0;0;0;0;0;0;0;0;0;0;0;0;0;0;0;0;0;0;0;0;0;0;0;0;0;0;0;0;0;0;0;0;0 | Q7: 0;15;15;1;15;15;15;15;15;15;15;15;15;15;15;15;15;15;15;15;15;15;15;15;15;15;15;15;15;15;15;15;15;15;15;15;15;15;15;15;15;15;15;15;15;15;15;15;15;15;15;15;15;15;15;15;15;15;15;15;15;15;15;15 | R7: 15.2
A8: R8862A S9000(A6A) | B8: 900 | C8: =填表说明!$AW$4 -> 84 | D8: & | E8: :1 | F8: :2 | G8: :3 | H8: :4 | M8: =A8&C8 -> R8862A S9000(A6A)84 | N8: =C8&E8&";"&C8&H8 -> 84:1;84:4 | P8: 1;0;0;1;0;0;0;0;0;0;0;0;0;0;0;0;0;0;0;0;0;0;0;0;0;0;0;0;0;0;0;0;0;0;0;0;0;0;0;0;0;0;0;0;0;0;0;0;0;0;0;0;0;0;0;0;0;0;0;0;0;0;0;0 | Q8: 0;15;15;1;15;15;15;15;15;15;15;15;15;15;15;15;15;15;15;15;15;15;15;15;15;15;15;15;15;15;15;15;15;15;15;15;15;15;15;15;15;15;15;15;15;15;15;15;15;15;15;15;15;15;15;15;15;15;15;15;15;15;15;15 | R8: 15.2
A9: R8882 S1800(B6B) | B9: 1800 | C9: =填表说明!$AW$4 -> 84 | D9: & | E9: :1 | F9: :2 | G9: :3 | H9: :4 | M9: =A9&C9 -> R8882 S1800(B6B)84 | N9: =C9&E9&";"&C9&H9 -> 84:1;84:4 | P9: 1;0;0;1;0;0;0;0;0;0;0;0;0;0;0;0;0;0;0;0;0;0;0;0;0;0;0;0;0;0;0;0;0;0;0;0;0;0;0;0;0;0;0;0;0;0;0;0;0;0;0;0;0;0;0;0;0;0;0;0;0;0;0;0 | Q9: 0;15;15;1;15;15;15;15;15;15;15;15;15;15;15;15;15;15;15;15;15;15;15;15;15;15;15;15;15;15;15;15;15;15;15;15;15;15;15;15;15;15;15;15;15;15;15;15;15;15;15;15;15;15;15;15;15;15;15;15;15;15;15;15 | R9: 15.2
A10: R8852E S9000(A8A) | B10: 900 | C10: =填表说明!$AW$5 -> 85 | D10: & | E10: :1 | F10: :2 | G10: :3 | H10: :4 | M10: =A10&C10 -> R8852E S9000(A8A)85 | N10: =C10&E10&";"&C10&H10 -> 85:1;85:4 | P10: 1;0;0;1;0;0;0;0;0;0;0;0;0;0;0;0;0;0;0;0;0;0;0;0;0;0;0;0;0;0;0;0;0;0;0;0;0;0;0;0;0;0;0;0;0;0;0;0;0;0;0;0;0;0;0;0;0;0;0;0;0;0;0;0 | Q10: 0;15;15;1;15;15;15;15;15;15;15;15;15;15;15;15;15;15;15;15;15;15;15;15;15;15;15;15;15;15;15;15;15;15;15;15;15;15;15;15;15;15;15;15;15;15;15;15;15;15;15;15;15;15;15;15;15;15;15;15;15;15;15;15 | R10: 15.2
A11: R8852E S1800(A8A) | B11: 1800 | C11: =填表说明!$AW$5 -> 85 | D11: & | E11: :1 | F11: :2 | G11: :3 | H11: :4 | M11: =A11&C11 -> R8852E S1800(A8A)85 | N11: =C11&E11&";"&C11&H11 -> 85:1;85:4 | P11: 1;0;0;1;0;0;0;0;0;0;0;0;0;0;0;0;0;0;0;0;0;0;0;0;0;0;0;0;0;0;0;0;0;0;0;0;0;0;0;0;0;0;0;0;0;0;0;0;0;0;0;0;0;0;0;0;0;0;0;0;0;0;0;0 | Q11: 0;15;15;1;15;15;15;15;15;15;15;15;15;15;15;15;15;15;15;15;15;15;15;15;15;15;15;15;15;15;15;15;15;15;15;15;15;15;15;15;15;15;15;15;15;15;15;15;15;15;15;15;15;15;15;15;15;15;15;15;15;15;15;15 | R11: 15.2
A12: R8854E S1800(A6A) | B12: 1800 | C12: =填表说明!$AW$5 -> 85 | D12: & | E12: :1 | F12: :2 | G12: :3 | H12: :4 | M12: =A12&C12 -> R8854E S1800(A6A)85 | N12: =C12&E12&";"&C12&F12&";"&C12&G12&";"&C12&H12 -> 85:1;85:2;85:3;85:4 | P12: 1;1;1;1;0;0;0;0;0;0;0;0;0;0;0;0;0;0;0;0;0;0;0;0;0;0;0;0;0;0;0;0;0;0;0;0;0;0;0;0;0;0;0;0;0;0;0;0;0;0;0;0;0;0;0;0;0;0;0;0;0;0;0;0 | Q12: 0;1;2;3;15;15;15;15;15;15;15;15;15;15;15;15;15;15;15;15;15;15;15;15;15;15;15;15;15;15;15;15;15;15;15;15;15;15;15;15;15;15;15;15;15;15;15;15;15;15;15;15;15;15;15;15;15;15;15;15;15;15;15;15 | R12: 15.2
A13: R8862A S1800(B6A) | B13: 1800 | C13: =填表说明!$AW$5 -> 85 | D13: & | E13: :1 | F13: :2 | G13: :3 | H13: :4 | M13: =A13&C13 -> R8862A S1800(B6A)85 | N13: =C13&E13&";"&C13&H13 -> 85:1;85:4 | P13: 1;0;0;1;0;0;0;0;0;0;0;0;0;0;0;0;0;0;0;0;0;0;0;0;0;0;0;0;0;0;0;0;0;0;0;0;0;0;0;0;0;0;0;0;0;0;0;0;0;0;0;0;0;0;0;0;0;0;0;0;0;0;0;0 | Q13: 0;15;15;1;15;15;15;15;15;15;15;15;15;15;15;15;15;15;15;15;15;15;15;15;15;15;15;15;15;15;15;15;15;15;15;15;15;15;15;15;15;15;15;15;15;15;15;15;15;15;15;15;15;15;15;15;15;15;15;15;15;15;15;15 | R13: 15.2
A14: R8854 S1800(A4A) | B14: 1800 | C14: =填表说明!$AW$5 -> 85 | D14: & | E14: :1 | F14: :2 | G14: :3 | H14: :4 | M14: =A14&C14 -> R8854 S1800(A4A)85 | N14: =C14&E14&";"&C14&F14&";"&C14&G14&";"&C14&H14 -> 85:1;85:2;85:3;85:4 | P14: 1;1;1;1;0;0;0;0;0;0;0;0;0;0;0;0;0;0;0;0;0;0;0;0;0;0;0;0;0;0;0;0;0;0;0;0;0;0;0;0;0;0;0;0;0;0;0;0;0;0;0;0;0;0;0;0;0;0;0;0;0;0;0;0 | Q14: 0;1;2;3;15;15;15;15;15;15;15;15;15;15;15;15;15;15;15;15;15;15;15;15;15;15;15;15;15;15;15;15;15;15;15;15;15;15;15;15;15;15;15;15;15;15;15;15;15;15;15;15;15;15;15;15;15;15;15;15;15;15;15;15 | R14: 15.2
A15: R8862A S1800(B6B) | B15: 1800 | C15: =填表说明!$AW$5 -> 85 | D15: & | E15: :1 | F15: :2 | G15: :3 | H15: :4 | M15: =A15&C15 -> R8862A S1800(B6B)85 | N15: =C15&E15&";"&C15&H15 -> 85:1;85:4 | P15: 1;0;0;1;0;0;0;0;0;0;0;0;0;0;0;0;0;0;0;0;0;0;0;0;0;0;0;0;0;0;0;0;0;0;0;0;0;0;0;0;0;0;0;0;0;0;0;0;0;0;0;0;0;0;0;0;0;0;0;0;0;0;0;0 | Q15: 0;15;15;1;15;15;15;15;15;15;15;15;15;15;15;15;15;15;15;15;15;15;15;15;15;15;15;15;15;15;15;15;15;15;15;15;15;15;15;15;15;15;15;15;15;15;15;15;15;15;15;15;15;15;15;15;15;15;15;15;15;15;15;15 | R15: 15.2
A16: R8862A S9000(A6A) | B16: 900 | C16: =填表说明!$AW$5 -> 85 | D16: & | E16: :1 | F16: :2 | G16: :3 | H16: :4 | M16: =A16&C16 -> R8862A S9000(A6A)85 | N16: =C16&E16&";"&C16&H16 -> 85:1;85:4 | P16: 1;0;0;1;0;0;0;0;0;0;0;0;0;0;0;0;0;0;0;0;0;0;0;0;0;0;0;0;0;0;0;0;0;0;0;0;0;0;0;0;0;0;0;0;0;0;0;0;0;0;0;0;0;0;0;0;0;0;0;0;0;0;0;0 | Q16: 0;15;15;1;15;15;15;15;15;15;15;15;15;15;15;15;15;15;15;15;15;15;15;15;15;15;15;15;15;15;15;15;15;15;15;15;15;15;15;15;15;15;15;15;15;15;15;15;15;15;15;15;15;15;15;15;15;15;15;15;15;15;15;15 | R16: 15.2
A17: R8882 S1800(B6B) | B17: 1800 | C17: =填表说明!$AW$5 -> 85 | D17: & | E17: :1 | F17: :2 | G17: :3 | H17: :4 | M17: =A17&C17 -> R8882 S1800(B6B)85 | N17: =C17&E17&";"&C17&H17 -> 85:1;85:4 | P17: 1;0;0;1;0;0;0;0;0;0;0;0;0;0;0;0;0;0;0;0;0;0;0;0;0;0;0;0;0;0;0;0;0;0;0;0;0;0;0;0;0;0;0;0;0;0;0;0;0;0;0;0;0;0;0;0;0;0;0;0;0;0;0;0 | Q17: 0;15;15;1;15;15;15;15;15;15;15;15;15;15;15;15;15;15;15;15;15;15;15;15;15;15;15;15;15;15;15;15;15;15;15;15;15;15;15;15;15;15;15;15;15;15;15;15;15;15;15;15;15;15;15;15;15;15;15;15;15;15;15;15 | R17: 15.2
A18: R8852E S9000(A8A) | B18: 900 | C18: =填表说明!$AW$6 -> 86 | D18: & | E18: :1 | F18: :2 | G18: :3 | H18: :4 | M18: =A18&C18 -> R8852E S9000(A8A)86 | N18: =C18&E18&";"&C18&H18 -> 86:1;86:4 | P18: 1;0;0;1;0;0;0;0;0;0;0;0;0;0;0;0;0;0;0;0;0;0;0;0;0;0;0;0;0;0;0;0;0;0;0;0;0;0;0;0;0;0;0;0;0;0;0;0;0;0;0;0;0;0;0;0;0;0;0;0;0;0;0;0 | Q18: 0;15;15;1;15;15;15;15;15;15;15;15;15;15;15;15;15;15;15;15;15;15;15;15;15;15;15;15;15;15;15;15;15;15;15;15;15;15;15;15;15;15;15;15;15;15;15;15;15;15;15;15;15;15;15;15;15;15;15;15;15;15;15;15 | R18: 15.2
A19: R8852E S1800(A8A) | B19: 1800 | C19: =填表说明!$AW$6 -> 86 | D19: & | E19: :1 | F19: :2 | G19: :3 | H19: :4 | M19: =A19&C19 -> R8852E S1800(A8A)86 | N19: =C19&E19&";"&C19&H19 -> 86:1;86:4 | P19: 1;0;0;1;0;0;0;0;0;0;0;0;0;0;0;0;0;0;0;0;0;0;0;0;0;0;0;0;0;0;0;0;0;0;0;0;0;0;0;0;0;0;0;0;0;0;0;0;0;0;0;0;0;0;0;0;0;0;0;0;0;0;0;0 | Q19: 0;15;15;1;15;15;15;15;15;15;15;15;15;15;15;15;15;15;15;15;15;15;15;15;15;15;15;15;15;15;15;15;15;15;15;15;15;15;15;15;15;15;15;15;15;15;15;15;15;15;15;15;15;15;15;15;15;15;15;15;15;15;15;15 | R19: 15.2
A20: R8854E S1800(A6A) | B20: 1800 | C20: =填表说明!$AW$6 -> 86 | D20: & | E20: :1 | F20: :2 | G20: :3 | H20: :4 | M20: =A20&C20 -> R8854E S1800(A6A)86 | N20: =C20&E20&";"&C20&F20&";"&C20&G20&";"&C20&H20 -> 86:1;86:2;86:3;86:4 | P20: 1;1;1;1;0;0;0;0;0;0;0;0;0;0;0;0;0;0;0;0;0;0;0;0;0;0;0;0;0;0;0;0;0;0;0;0;0;0;0;0;0;0;0;0;0;0;0;0;0;0;0;0;0;0;0;0;0;0;0;0;0;0;0;0 | Q20: 0;1;2;3;15;15;15;15;15;15;15;15;15;15;15;15;15;15;15;15;15;15;15;15;15;15;15;15;15;15;15;15;15;15;15;15;15;15;15;15;15;15;15;15;15;15;15;15;15;15;15;15;15;15;15;15;15;15;15;15;15;15;15;15 | R20: 15.2
A21: R8862A S1800(B6A) | B21: 1800 | C21: =填表说明!$AW$6 -> 86 | D21: & | E21: :1 | F21: :2 | G21: :3 | H21: :4 | M21: =A21&C21 -> R8862A S1800(B6A)86 | N21: =C21&E21&";"&C21&H21 -> 86:1;86:4 | P21: 1;0;0;1;0;0;0;0;0;0;0;0;0;0;0;0;0;0;0;0;0;0;0;0;0;0;0;0;0;0;0;0;0;0;0;0;0;0;0;0;0;0;0;0;0;0;0;0;0;0;0;0;0;0;0;0;0;0;0;0;0;0;0;0 | Q21: 0;15;15;1;15;15;15;15;15;15;15;15;15;15;15;15;15;15;15;15;15;15;15;15;15;15;15;15;15;15;15;15;15;15;15;15;15;15;15;15;15;15;15;15;15;15;15;15;15;15;15;15;15;15;15;15;15;15;15;15;15;15;15;15 | R21: 15.2
A22: R8854 S1800(A4A) | B22: 1800 | C22: =填表说明!$AW$6 -> 86 | D22: & | E22: :1 | F22: :2 | G22: :3 | H22: :4 | M22: =A22&C22 -> R8854 S1800(A4A)86 | N22: =C22&E22&";"&C22&F22&";"&C22&G22&";"&C22&H22 -> 86:1;86:2;86:3;86:4 | P22: 1;1;1;1;0;0;0;0;0;0;0;0;0;0;0;0;0;0;0;0;0;0;0;0;0;0;0;0;0;0;0;0;0;0;0;0;0;0;0;0;0;0;0;0;0;0;0;0;0;0;0;0;0;0;0;0;0;0;0;0;0;0;0;0 | Q22: 0;1;2;3;15;15;15;15;15;15;15;15;15;15;15;15;15;15;15;15;15;15;15;15;15;15;15;15;15;15;15;15;15;15;15;15;15;15;15;15;15;15;15;15;15;15;15;15;15;15;15;15;15;15;15;15;15;15;15;15;15;15;15;15 | R22: 15.2
A23: R8862A S1800(B6B) | B23: 1800 | C23: =填表说明!$AW$6 -> 86 | D23: & | E23: :1 | F23: :2 | G23: :3 | H23: :4 | M23: =A23&C23 -> R8862A S1800(B6B)86 | N23: =C23&E23&";"&C23&H23 -> 86:1;86:4 | P23: 1;0;0;1;0;0;0;0;0;0;0;0;0;0;0;0;0;0;0;0;0;0;0;0;0;0;0;0;0;0;0;0;0;0;0;0;0;0;0;0;0;0;0;0;0;0;0;0;0;0;0;0;0;0;0;0;0;0;0;0;0;0;0;0 | Q23: 0;15;15;1;15;15;15;15;15;15;15;15;15;15;15;15;15;15;15;15;15;15;15;15;15;15;15;15;15;15;15;15;15;15;15;15;15;15;15;15;15;15;15;15;15;15;15;15;15;15;15;15;15;15;15;15;15;15;15;15;15;15;15;15 | R23: 15.2
A24: R8862A S9000(A6A) | B24: 900 | C24: =填表说明!$AW$6 -> 86 | D24: & | E24: :1 | F24: :2 | G24: :3 | H24: :4 | M24: =A24&C24 -> R8862A S9000(A6A)86 | N24: =C24&E24&";"&C24&H24 -> 86:1;86:4 | P24: 1;0;0;1;0;0;0;0;0;0;0;0;0;0;0;0;0;0;0;0;0;0;0;0;0;0;0;0;0;0;0;0;0;0;0;0;0;0;0;0;0;0;0;0;0;0;0;0;0;0;0;0;0;0;0;0;0;0;0;0;0;0;0;0 | Q24: 0;15;15;1;15;15;15;15;15;15;15;15;15;15;15;15;15;15;15;15;15;15;15;15;15;15;15;15;15;15;15;15;15;15;15;15;15;15;15;15;15;15;15;15;15;15;15;15;15;15;15;15;15;15;15;15;15;15;15;15;15;15;15;15 | R24: 15.2
A25: R8882 S1800(B6B) | B25: 1800 | C25: =填表说明!$AW$6 -> 86 | D25: & | E25: :1 | F25: :2 | G25: :3 | H25: :4 | M25: =A25&C25 -> R8882 S1800(B6B)86 | N25: =C25&E25&";"&C25&H25 -> 86:1;86:4 | P25: 1;0;0;1;0;0;0;0;0;0;0;0;0;0;0;0;0;0;0;0;0;0;0;0;0;0;0;0;0;0;0;0;0;0;0;0;0;0;0;0;0;0;0;0;0;0;0;0;0;0;0;0;0;0;0;0;0;0;0;0;0;0;0;0 | Q25: 0;15;15;1;15;15;15;15;15;15;15;15;15;15;15;15;15;15;15;15;15;15;15;15;15;15;15;15;15;15;15;15;15;15;15;15;15;15;15;15;15;15;15;15;15;15;15;15;15;15;15;15;15;15;15;15;15;15;15;15;15;15;15;15 | R25: 15.2
A26: TDD
A27: RRU型号 | B27: 支持频段 | N27: IrAntGroup-连接的发射设备 | O27: IrAntGroup-使用的天线属性 | P27: Cell4GTDD-上行激活天线位图(小区复位生效) | Q27: Cell4GTDD-天线端口与天线通道的映射关系 | R27: 开通默认配置功率 | S27: 小区模式（小区复位生效） | T27: 使用的天线属性
A28: A8712 M192026 | B28: F1/F2/A | C28: =填表说明!$AW$4 -> 84 | D28: & | E28: :1 | F28: :2 | M28: =A28&C28 -> A8712 M19202684 | N28: =C28&E28&D28&C28&F28 -> 84:1&84:2 | O28: 202 | P28: 1;1;0;0;0;0;0;0;0;0;0;0;0;0;0;0;0;0;0;0;0;0;0;0;0;0;0;0;0;0;0;0;0;0;0;0;0;0;0;0;0;0;0;0;0;0;0;0;0;0;0;0;0;0;0;0;0;0;0;0;0;0;0;0 | Q28: 0;1;15;15;15;15;15;15;15;15;15;15;15;15;15;15;15;15;15;15;15;15;15;15;15;15;15;15;15;15;15;15;15;15;15;15;15;15;15;15;15;15;15;15;15;15;15;15;15;15;15;15;15;15;15;15;15;15;15;15;15;15;15;15 | R28: 12.2 | S28: 0 | T28: 202
A29: A8712 M192026 | B29: D1/D2/D3 | C29: =填表说明!$AW$4 -> 84 | D29: & | E29: :3 | F29: :4 | M29: =A29&C29 -> A8712 M19202684 | N29: =C29&E29&D29&C29&F29 -> 84:3&84:4 | O29: 202 | P29: 0;0;1;1;0;0;0;0;0;0;0;0;0;0;0;0;0;0;0;0;0;0;0;0;0;0;0;0;0;0;0;0;0;0;0;0;0;0;0;0;0;0;0;0;0;0;0;0;0;0;0;0;0;0;0;0;0;0;0;0;0;0;0;0 | Q29: 15;15;0;1;15;15;15;15;15;15;15;15;15;15;15;15;15;15;15;15;15;15;15;15;15;15;15;15;15;15;15;15;15;15;15;15;15;15;15;15;15;15;15;15;15;15;15;15;15;15;15;15;15;15;15;15;15;15;15;15;15;15;15;15 | R29: 12.2 | S29: 0 | T29: 202
A30: A8724 M192026 | B30: F1/F2/A | C30: =填表说明!$AW$4 -> 84 | D30: & | E30: :1 | F30: :2 | G30: :3 | H30: :4 | M30: =A30&C30 -> A8724 M19202684 | N30: =C30&E30&D30&C30&F30&D30&C30&G30&D30&C30&H30 -> 84:1&84:2&84:3&84:4 | O30: 351 | P30: 1;1;1;1;0;0;0;0;0;0;0;0;0;0;0;0;0;0;0;0;0;0;0;0;0;0;0;0;0;0;0;0;0;0;0;0;0;0;0;0;0;0;0;0;0;0;0;0;0;0;0;0;0;0;0;0;0;0;0;0;0;0;0;0 | Q30: 0;0;1;1;15;15;15;15;15;15;15;15;15;15;15;15;15;15;15;15;15;15;15;15;15;15;15;15;15;15;15;15;15;15;15;15;15;15;15;15;15;15;15;15;15;15;15;15;15;15;15;15;15;15;15;15;15;15;15;15;15;15;15;15 | R30: 12.2 | S30: 1 | T30: 202
A31: A8724 M192026 | B31: D3/D7/D8 | C31: =填表说明!$AW$4 -> 84 | D31: & | E31: :5 | F31: :6 | G31: :7 | H31: :8 | M31: =A31&C31 -> A8724 M19202684 | N31: =C31&E31&D31&C31&F31&D31&C31&G31&D31&C31&H31 -> 84:5&84:6&84:7&84:8 | O31: 351 | P31: 0;0;0;0;1;1;1;1;0;0;0;0;0;0;0;0;0;0;0;0;0;0;0;0;0;0;0;0;0;0;0;0;0;0;0;0;0;0;0;0;0;0;0;0;0;0;0;0;0;0;0;0;0;0;0;0;0;0;0;0;0;0;0;0 | Q31: 15;15;15;15;0;0;1;1;15;15;15;15;15;15;15;15;15;15;15;15;15;15;15;15;15;15;15;15;15;15;15;15;15;15;15;15;15;15;15;15;15;15;15;15;15;15;15;15;15;15;15;15;15;15;15;15;15;15;15;15;15;15;15;15 | R31: 12.2 | S31: 1 | T31: 202
A32: R8502 S2300 | B32: E1/E2/E3 | C32: =填表说明!$AW$4 -> 84 | D32: & | E32: :2 | M32: =A32&C32 -> R8502 S230084 | N32: =C32&E32 -> 84:2 | O32: 201 | P32: 0;1;0;0;0;0;0;0;0;0;0;0;0;0;0;0;0;0;0;0;0;0;0;0;0;0;0;0;0;0;0;0;0;0;0;0;0;0;0;0;0;0;0;0;0;0;0;0;0;0;0;0;0;0;0;0;0;0;0;0;0;0;0;0 | Q32: 15;0;15;15;15;15;15;15;15;15;15;15;15;15;15;15;15;15;15;15;15;15;15;15;15;15;15;15;15;15;15;15;15;15;15;15;15;15;15;15;15;15;15;15;15;15;15;15;15;15;15;15;15;15;15;15;15;15;15;15;15;15;15;15 | R32: 12.2 | S32: 0 | T32: 202
A33: R8502 S2600 | B33: D1/D2/D3 | C33: =填表说明!$AW$4 -> 84 | D33: & | E33: :1 | F33: :2 | M33: =A33&C33 -> R8502 S260084 | N33: =C33&E33&D33&C33&F33 -> 84:1&84:2 | O33: 双通道配置202；单通道配置201 | P33: 1;1;0;0;0;0;0;0;0;0;0;0;0;0;0;0;0;0;0;0;0;0;0;0;0;0;0;0;0;0;0;0;0;0;0;0;0;0;0;0;0;0;0;0;0;0;0;0;0;0;0;0;0;0;0;0;0;0;0;0;0;0;0;0 | Q33: 0;1;15;15;15;15;15;15;15;15;15;15;15;15;15;15;15;15;15;15;15;15;15;15;15;15;15;15;15;15;15;15;15;15;15;15;15;15;15;15;15;15;15;15;15;15;15;15;15;15;15;15;15;15;15;15;15;15;15;15;15;15;15;15 | R33: 12.2 | S33: 0 | T33: 202
A34: R8502E S2600 | B34: D1/D2/D3 | C34: =填表说明!$AW$4 -> 84 | D34: & | E34: :1 | F34: :2 | M34: =A34&C34 -> R8502E S260084 | N34: =C34&E34&D34&C34&F34 -> 84:1&84:2 | O34: 双通道配置202；单通道配置201 | P34: 1;1;0;0;0;0;0;0;0;0;0;0;0;0;0;0;0;0;0;0;0;0;0;0;0;0;0;0;0;0;0;0;0;0;0;0;0;0;0;0;0;0;0;0;0;0;0;0;0;0;0;0;0;0;0;0;0;0;0;0;0;0;0;0 | Q34: 0;1;15;15;15;15;15;15;15;15;15;15;15;15;15;15;15;15;15;15;15;15;15;15;15;15;15;15;15;15;15;15;15;15;15;15;15;15;15;15;15;15;15;15;15;15;15;15;15;15;15;15;15;15;15;15;15;15;15;15;15;15;15;15 | R34: 12.2 | S34: 0 | T34: 202
A35: R8968E M1920 | B35: F1/F2/A | C35: =填表说明!$AW$4 -> 84 | D35: & | E35: :1 | F35: :2 | G35: :3 | H35: :4 | I35: :5 | J35: :6 | K35: :7 | L35: :8 | M35: =A35&C35 -> R8968E M192084 | N35: =C35&E35&D35&C35&F35&D35&C35&G35&D35&C35&H35&D35&C35&I35&D35&C35&J35&D35&C35&K35&D35&C35&L35 -> 84:1&84:2&84:3&84:4&84:5&84:6&84:7&84:8 | O35: 16 | P35: 1;1;1;1;1;1;1;1;0;0;0;0;0;0;0;0;0;0;0;0;0;0;0;0;0;0;0;0;0;0;0;0;0;0;0;0;0;0;0;0;0;0;0;0;0;0;0;0;0;0;0;0;0;0;0;0;0;0;0;0;0;0;0;0 | Q35: 0;0;0;0;1;1;1;1;15;15;15;15;15;15;15;15;15;15;15;15;15;15;15;15;15;15;15;15;15;15;15;15;15;15;15;15;15;15;15;15;15;15;15;15;15;15;15;15;15;15;15;15;15;15;15;15;15;15;15;15;15;15;15;15 | R35: 15.2 | S35: 1 | T35: 16
A36: R8972 M1920 | B36: F1/F2/A | C36: =填表说明!$AW$4 -> 84 | D36: & | E36: :1 | F36: :2 | M36: =A36&C36 -> R8972 M192084 | N36: =C36&E36&D36&C36&F36 -> 84:1&84:2 | O36: 双通道配置202；单通道配置201 | P36: 1;1;0;0;0;0;0;0;0;0;0;0;0;0;0;0;0;0;0;0;0;0;0;0;0;0;0;0;0;0;0;0;0;0;0;0;0;0;0;0;0;0;0;0;0;0;0;0;0;0;0;0;0;0;0;0;0;0;0;0;0;0;0;0 | Q36: 0;1;15;15;15;15;15;15;15;15;15;15;15;15;15;15;15;15;15;15;15;15;15;15;15;15;15;15;15;15;15;15;15;15;15;15;15;15;15;15;15;15;15;15;15;15;15;15;15;15;15;15;15;15;15;15;15;15;15;15;15;15;15;15 | R36: 15.2 | S36: 0 | T36: 202
A37: R8972 M192023 | B37: F1/F2/A | C37: =填表说明!$AW$4 -> 84 | D37: & | E37: :1 | M37: =A37&C37 -> R8972 M19202384 | N37: =C37&E37 -> 84:1 | O37: 201 | P37: 1;0;0;0;0;0;0;0;0;0;0;0;0;0;0;0;0;0;0;0;0;0;0;0;0;0;0;0;0;0;0;0;0;0;0;0;0;0;0;0;0;0;0;0;0;0;0;0;0;0;0;0;0;0;0;0;0;0;0;0;0;0;0;0 | Q37: 0;15;15;15;15;15;15;15;15;15;15;15;15;15;15;15;15;15;15;15;15;15;15;15;15;15;15;15;15;15;15;15;15;15;15;15;15;15;15;15;15;15;15;15;15;15;15;15;15;15;15;15;15;15;15;15;15;15;15;15;15;15;15;15 | R37: 15.2 | S37: 0 | T37: 202
A38: R8972 M192023 | B38: E1/E2/E3 | C38: =填表说明!$AW$4 -> 84 | D38: & | E38: :2 | M38: =A38&C38 -> R8972 M19202384 | N38: =C38&E38 -> 84:2 | O38: 201 | P38: 0;1;0;0;0;0;0;0;0;0;0;0;0;0;0;0;0;0;0;0;0;0;0;0;0;0;0;0;0;0;0;0;0;0;0;0;0;0;0;0;0;0;0;0;0;0;0;0;0;0;0;0;0;0;0;0;0;0;0;0;0;0;0;0 | Q38: 15;0;15;15;15;15;15;15;15;15;15;15;15;15;15;15;15;15;15;15;15;15;15;15;15;15;15;15;15;15;15;15;15;15;15;15;15;15;15;15;15;15;15;15;15;15;15;15;15;15;15;15;15;15;15;15;15;15;15;15;15;15;15;15 | R38: 15.2 | S38: 0 | T38: 202
A39: R8972 S2300 | B39: E1/E2/E3 | C39: =填表说明!$AW$4 -> 84 | D39: & | E39: :1 | F39: :2 | M39: =A39&C39 -> R8972 S230084 | N39: =C39&E39&D39&C39&F39 -> 84:1&84:2 | O39: 双通道配置202；单通道配置201 | P39: 1;1;0;0;0;0;0;0;0;0;0;0;0;0;0;0;0;0;0;0;0;0;0;0;0;0;0;0;0;0;0;0;0;0;0;0;0;0;0;0;0;0;0;0;0;0;0;0;0;0;0;0;0;0;0;0;0;0;0;0;0;0;0;0 | Q39: 0;1;15;15;15;15;15;15;15;15;15;15;15;15;15;15;15;15;15;15;15;15;15;15;15;15;15;15;15;15;15;15;15;15;15;15;15;15;15;15;15;15;15;15;15;15;15;15;15;15;15;15;15;15;15;15;15;15;15;15;15;15;15;15 | R39: 15.2 | S39: 0 | T39: 202
A40: R8972E M1920 | B40: F1/F2/A | C40: =填表说明!$AW$4 -> 84 | D40: & | E40: :1 | F40: :2 | M40: =A40&C40 -> R8972E M192084 | N40: =C40&E40&D40&C40&F40 -> 84:1&84:2 | O40: 双通道配置202；单通道配置201 | P40: 1;1;0;0;0;0;0;0;0;0;0;0;0;0;0;0;0;0;0;0;0;0;0;0;0;0;0;0;0;0;0;0;0;0;0;0;0;0;0;0;0;0;0;0;0;0;0;0;0;0;0;0;0;0;0;0;0;0;0;0;0;0;0;0 | Q40: 0;1;15;15;15;15;15;15;15;15;15;15;15;15;15;15;15;15;15;15;15;15;15;15;15;15;15;15;15;15;15;15;15;15;15;15;15;15;15;15;15;15;15;15;15;15;15;15;15;15;15;15;15;15;15;15;15;15;15;15;15;15;15;15 | R40: 15.2 | S40: 0 | T40: 202
...

Sheet SCTP描述信息
A1: 远端IP地址 | B1: SCTP描述信息 | D1: 2;16;32;64 | E1: UniRan 12.3(GFTLN V5.50.51)
A2: 10.178.55.160;10.178.55.161 | B2: APP-BJBFbjAMF001BHW-01BHW012 | D2: 2;32 | E2: UniRan 12.3(GTDL V5.50.51)
A3: 10.178.55.162;10.178.55.163 | B3: APP-BJBFbjAMF003BHW-01BHW011 | D3: 16;32 | E3: UniRan 12.4(LTE V5.50.51)
A4: 10.178.55.164;10.178.55.165 | B4: APP-BJBFbjAMF005BHW-01BHW012 | D4: 2;16;64 | E4: UniRan 12.3(GLN V5.50.51)
A5: 10.178.55.166;10.178.55.167 | B5: APP-BJBFbjAMF007BHW-01BHW011 | D5: 16 | E5: UniRan 12.4(LTE V5.50.51)
A6: 10.178.55.32;10.178.55.33 | B6: APP-BJLAFbjAMF002BHW-01BHW012 | D6: 32 | E6: UniRan 12.4(LTE V5.50.51)
A7: 10.178.55.34;10.178.55.35 | B7: APP-BJLAFbjAMF004BHW-01BHW011
A8: 10.178.55.36;10.178.55.37 | B8: APP-BJLAFbjAMF006BHW-01BHW012
A9: 10.178.55.38;10.178.55.39 | B9: APP-BJLAFbjAMF008BHW-01BHW011
A10: 10.69.189.48;10.69.189.49 | B10: CBN
A11: 10.69.189.160;10.69.189.161 | B11: CBN
